Workbook

Sheet SUMMARY
A1: LỊCH CRAWL VPS BỔ SUNG — 24/08/2026 ĐẾN 30/11/2026
A3: Thông số | B3: Giá trị | D3: Kiểm tra | E3: Kết quả
A4: Ngày bắt đầu | B4: 46258 | D4: Số ngày mong đợi | E4: 99
A5: Ngày kết thúc | B5: 46356 | D5: Số dòng lịch thực tế | E5: =B8 -> 99
A6: Giờ bắt đầu mỗi ngày | B6: 00:30 | D6: Mỗi ngày đủ 5 check-in | E6: =IF(COUNTIF(VPS_CRAWL_PLAN!$L$4:$L$102,"PASS")=$E$4,"PASS","CHECK") -> PASS
A7: Múi giờ | B7: Asia/Ho_Chi_Minh | D7: Không trùng 12 ngày local | E7: =IF(COUNTIF(VPS_CRAWL_PLAN!$M$4:$M$102,"PASS")=$E$4,"PASS","CHECK") -> PASS
A8: Tổng số ngày theo lịch | B8: =ROWS(VPS_CRAWL_PLAN!$A$4:$A$102) -> 99 | D8: Trạng thái workbook | E8: =IF(AND(E4=E5,E6="PASS",E7="PASS"),"PASS","CHECK") -> PASS
A9: Số khách sạn | B9: 354
A10: Check-in mỗi ngày | B10: 5
A11: Item dự kiến mỗi ngày | B11: 1770
A12: Đã hoàn thành | B12: =COUNTIF(CRAWL_LOG!$B$4:$B$102,"Hoàn thành")+COUNTIF(CRAWL_LOG!$B$4:$B$102,"Hoàn thành có lỗi") -> 45
A13: Chưa chạy | B13: =COUNTIF(CRAWL_LOG!$B$4:$B$102,"Chưa chạy") -> 53
A15: VPS theo dõi 5 anchor bổ sung có chủ đích. Mỗi ngày được đối chiếu trực tiếp với 12 ngày local; không chọn ngẫu nhiên lại và không dùng slot trùng local.

Sheet VPS_CRAWL_PLAN
A1: VPS CRAWL PLAN — 99 NGÀY, 5 CHECK-IN BỔ SUNG MỖI NGÀY
A2: V1–V5 là anchor bổ sung. Tất cả check-in phải >= crawl date, khác nhau và không xuất hiện trong 12 slot local của cùng ngày crawl.
A3: Crawl date | B3: Thứ | C3: Phase | D3: Start time (ICT) | E3: V1 weekday | F3: V2 weekend | G3: V3 seasonal | H3: V4 medium | I3: V5 long | J3: Min lead | K3: Max lead | L3: 5 ngày hợp lệ | M3: Không trùng local | N3: Crawl status | O3: Sampling note
A4: 46258 | B4: Thứ Hai | C4: Warm-up | D4: 00:30 | E4: 46261 | F4: 46264 | G4: 46268 | H4: 46281 | I4: 46411 | J4: =MIN(E4:I4)-A4 -> 3 | K4: =MAX(E4:I4)-A4 -> 153 | L4: =IF(AND(COUNT(E4:I4)=5,MIN(E4:I4)>=A4,E4<>F4,E4<>G4,E4<>H4,E4<>I4,F4<>G4,F4<>H4,F4<>I4,G4<>H4,G4<>I4,H4<>I4),"PASS","CHECK") -> PASS | M4: =IF(COUNTIF(LOCAL_REFERENCE!$D4:$O4,E4)+COUNTIF(LOCAL_REFERENCE!$D4:$O4,F4)+COUNTIF(LOCAL_REFERENCE!$D4:$O4,G4)+COUNTIF(LOCAL_REFERENCE!$D4:$O4,H4)+COUNTIF(LOCAL_REFERENCE!$D4:$O4,I4)=0,"PASS","DUPLICATE") -> PASS | N4: =CRAWL_LOG!B4 -> Hoàn thành | O4: Supplementary panel
A5: 46259 | B5: Thứ Ba | C5: Warm-up | D5: 00:30 | E5: 46261 | F5: 46264 | G5: 46268 | H5: 46281 | I5: 46411 | J5: =MIN(E5:I5)-A5 -> 2 | K5: =MAX(E5:I5)-A5 -> 152 | L5: =IF(AND(COUNT(E5:I5)=5,MIN(E5:I5)>=A5,E5<>F5,E5<>G5,E5<>H5,E5<>I5,F5<>G5,F5<>H5,F5<>I5,G5<>H5,G5<>I5,H5<>I5),"PASS","CHECK") -> PASS | M5: =IF(COUNTIF(LOCAL_REFERENCE!$D5:$O5,E5)+COUNTIF(LOCAL_REFERENCE!$D5:$O5,F5)+COUNTIF(LOCAL_REFERENCE!$D5:$O5,G5)+COUNTIF(LOCAL_REFERENCE!$D5:$O5,H5)+COUNTIF(LOCAL_REFERENCE!$D5:$O5,I5)=0,"PASS","DUPLICATE") -> PASS | N5: =CRAWL_LOG!B5 -> Hoàn thành | O5: Supplementary panel
A6: 46260 | B6: Thứ Tư | C6: Warm-up | D6: 00:30 | E6: 46261 | F6: 46264 | G6: 46268 | H6: 46281 | I6: 46411 | J6: =MIN(E6:I6)-A6 -> 1 | K6: =MAX(E6:I6)-A6 -> 151 | L6: =IF(AND(COUNT(E6:I6)=5,MIN(E6:I6)>=A6,E6<>F6,E6<>G6,E6<>H6,E6<>I6,F6<>G6,F6<>H6,F6<>I6,G6<>H6,G6<>I6,H6<>I6),"PASS","CHECK") -> PASS | M6: =IF(COUNTIF(LOCAL_REFERENCE!$D6:$O6,E6)+COUNTIF(LOCAL_REFERENCE!$D6:$O6,F6)+COUNTIF(LOCAL_REFERENCE!$D6:$O6,G6)+COUNTIF(LOCAL_REFERENCE!$D6:$O6,H6)+COUNTIF(LOCAL_REFERENCE!$D6:$O6,I6)=0,"PASS","DUPLICATE") -> PASS | N6: =CRAWL_LOG!B6 -> Hoàn thành | O6: Supplementary panel
A7: 46261 | B7: Thứ Năm | C7: Warm-up | D7: 00:30 | E7: 46261 | F7: 46264 | G7: 46268 | H7: 46281 | I7: 46411 | J7: =MIN(E7:I7)-A7 -> 0 | K7: =MAX(E7:I7)-A7 -> 150 | L7: =IF(AND(COUNT(E7:I7)=5,MIN(E7:I7)>=A7,E7<>F7,E7<>G7,E7<>H7,E7<>I7,F7<>G7,F7<>H7,F7<>I7,G7<>H7,G7<>I7,H7<>I7),"PASS","CHECK") -> PASS | M7: =IF(COUNTIF(LOCAL_REFERENCE!$D7:$O7,E7)+COUNTIF(LOCAL_REFERENCE!$D7:$O7,F7)+COUNTIF(LOCAL_REFERENCE!$D7:$O7,G7)+COUNTIF(LOCAL_REFERENCE!$D7:$O7,H7)+COUNTIF(LOCAL_REFERENCE!$D7:$O7,I7)=0,"PASS","DUPLICATE") -> PASS | N7: =CRAWL_LOG!B7 -> Hoàn thành có lỗi | O7: Supplementary panel
A8: 46262 | B8: Thứ Sáu | C8: Warm-up | D8: 00:30 | E8: 46289 | F8: 46264 | G8: 46268 | H8: 46281 | I8: 46411 | J8: =MIN(E8:I8)-A8 -> 2 | K8: =MAX(E8:I8)-A8 -> 149 | L8: =IF(AND(COUNT(E8:I8)=5,MIN(E8:I8)>=A8,E8<>F8,E8<>G8,E8<>H8,E8<>I8,F8<>G8,F8<>H8,F8<>I8,G8<>H8,G8<>I8,H8<>I8),"PASS","CHECK") -> PASS | M8: =IF(COUNTIF(LOCAL_REFERENCE!$D8:$O8,E8)+COUNTIF(LOCAL_REFERENCE!$D8:$O8,F8)+COUNTIF(LOCAL_REFERENCE!$D8:$O8,G8)+COUNTIF(LOCAL_REFERENCE!$D8:$O8,H8)+COUNTIF(LOCAL_REFERENCE!$D8:$O8,I8)=0,"PASS","DUPLICATE") -> PASS | N8: =CRAWL_LOG!B8 -> Hoàn thành có lỗi | O8: Supplementary panel
A9: 46263 | B9: Thứ Bảy | C9: Warm-up | D9: 00:30 | E9: 46289 | F9: 46264 | G9: 46268 | H9: 46281 | I9: 46411 | J9: =MIN(E9:I9)-A9 -> 1 | K9: =MAX(E9:I9)-A9 -> 148 | L9: =IF(AND(COUNT(E9:I9)=5,MIN(E9:I9)>=A9,E9<>F9,E9<>G9,E9<>H9,E9<>I9,F9<>G9,F9<>H9,F9<>I9,G9<>H9,G9<>I9,H9<>I9),"PASS","CHECK") -> PASS | M9: =IF(COUNTIF(LOCAL_REFERENCE!$D9:$O9,E9)+COUNTIF(LOCAL_REFERENCE!$D9:$O9,F9)+COUNTIF(LOCAL_REFERENCE!$D9:$O9,G9)+COUNTIF(LOCAL_REFERENCE!$D9:$O9,H9)+COUNTIF(LOCAL_REFERENCE!$D9:$O9,I9)=0,"PASS","DUPLICATE") -> PASS | N9: =CRAWL_LOG!B9 -> Hoàn thành có lỗi | O9: Supplementary panel
A10: 46264 | B10: Chủ Nhật | C10: Warm-up | D10: 00:30 | E10: 46289 | F10: 46264 | G10: 46268 | H10: 46281 | I10: 46411 | J10: =MIN(E10:I10)-A10 -> 0 | K10: =MAX(E10:I10)-A10 -> 147 | L10: =IF(AND(COUNT(E10:I10)=5,MIN(E10:I10)>=A10,E10<>F10,E10<>G10,E10<>H10,E10<>I10,F10<>G10,F10<>H10,F10<>I10,G10<>H10,G10<>I10,H10<>I10),"PASS","CHECK") -> PASS | M10: =IF(COUNTIF(LOCAL_REFERENCE!$D10:$O10,E10)+COUNTIF(LOCAL_REFERENCE!$D10:$O10,F10)+COUNTIF(LOCAL_REFERENCE!$D10:$O10,G10)+COUNTIF(LOCAL_REFERENCE!$D10:$O10,H10)+COUNTIF(LOCAL_REFERENCE!$D10:$O10,I10)=0,"PASS","DUPLICATE") -> PASS | N10: =CRAWL_LOG!B10 -> Hoàn thành có lỗi | O10: Supplementary panel
A11: 46265 | B11: Thứ Hai | C11: Warm-up | D11: 00:30 | E11: 46289 | F11: 46292 | G11: 46268 | H11: 46281 | I11: 46411 | J11: =MIN(E11:I11)-A11 -> 3 | K11: =MAX(E11:I11)-A11 -> 146 | L11: =IF(AND(COUNT(E11:I11)=5,MIN(E11:I11)>=A11,E11<>F11,E11<>G11,E11<>H11,E11<>I11,F11<>G11,F11<>H11,F11<>I11,G11<>H11,G11<>I11,H11<>I11),"PASS","CHECK") -> PASS | M11: =IF(COUNTIF(LOCAL_REFERENCE!$D11:$O11,E11)+COUNTIF(LOCAL_REFERENCE!$D11:$O11,F11)+COUNTIF(LOCAL_REFERENCE!$D11:$O11,G11)+COUNTIF(LOCAL_REFERENCE!$D11:$O11,H11)+COUNTIF(LOCAL_REFERENCE!$D11:$O11,I11)=0,"PASS","DUPLICATE") -> PASS | N11: =CRAWL_LOG!B11 -> Hoàn thành có lỗi | O11: Supplementary panel
A12: 46266 | B12: Thứ Ba | C12: Official | D12: 00:30 | E12: 46289 | F12: 46292 | G12: 46268 | H12: 46281 | I12: 46411 | J12: =MIN(E12:I12)-A12 -> 2 | K12: =MAX(E12:I12)-A12 -> 145 | L12: =IF(AND(COUNT(E12:I12)=5,MIN(E12:I12)>=A12,E12<>F12,E12<>G12,E12<>H12,E12<>I12,F12<>G12,F12<>H12,F12<>I12,G12<>H12,G12<>I12,H12<>I12),"PASS","CHECK") -> PASS | M12: =IF(COUNTIF(LOCAL_REFERENCE!$D12:$O12,E12)+COUNTIF(LOCAL_REFERENCE!$D12:$O12,F12)+COUNTIF(LOCAL_REFERENCE!$D12:$O12,G12)+COUNTIF(LOCAL_REFERENCE!$D12:$O12,H12)+COUNTIF(LOCAL_REFERENCE!$D12:$O12,I12)=0,"PASS","DUPLICATE") -> PASS | N12: =CRAWL_LOG!B12 -> Hoàn thành có lỗi | O12: Supplementary panel
A13: 46267 | B13: Thứ Tư | C13: Official | D13: 00:30 | E13: 46289 | F13: 46292 | G13: 46268 | H13: 46281 | I13: 46411 | J13: =MIN(E13:I13)-A13 -> 1 | K13: =MAX(E13:I13)-A13 -> 144 | L13: =IF(AND(COUNT(E13:I13)=5,MIN(E13:I13)>=A13,E13<>F13,E13<>G13,E13<>H13,E13<>I13,F13<>G13,F13<>H13,F13<>I13,G13<>H13,G13<>I13,H13<>I13),"PASS","CHECK") -> PASS | M13: =IF(COUNTIF(LOCAL_REFERENCE!$D13:$O13,E13)+COUNTIF(LOCAL_REFERENCE!$D13:$O13,F13)+COUNTIF(LOCAL_REFERENCE!$D13:$O13,G13)+COUNTIF(LOCAL_REFERENCE!$D13:$O13,H13)+COUNTIF(LOCAL_REFERENCE!$D13:$O13,I13)=0,"PASS","DUPLICATE") -> PASS | N13: =CRAWL_LOG!B13 -> Hoàn thành có lỗi | O13: Supplementary panel
A14: 46268 | B14: Thứ Năm | C14: Official | D14: 00:30 | E14: 46289 | F14: 46292 | G14: 46268 | H14: 46281 | I14: 46411 | J14: =MIN(E14:I14)-A14 -> 0 | K14: =MAX(E14:I14)-A14 -> 143 | L14: =IF(AND(COUNT(E14:I14)=5,MIN(E14:I14)>=A14,E14<>F14,E14<>G14,E14<>H14,E14<>I14,F14<>G14,F14<>H14,F14<>I14,G14<>H14,G14<>I14,H14<>I14),"PASS","CHECK") -> PASS | M14: =IF(COUNTIF(LOCAL_REFERENCE!$D14:$O14,E14)+COUNTIF(LOCAL_REFERENCE!$D14:$O14,F14)+COUNTIF(LOCAL_REFERENCE!$D14:$O14,G14)+COUNTIF(LOCAL_REFERENCE!$D14:$O14,H14)+COUNTIF(LOCAL_REFERENCE!$D14:$O14,I14)=0,"PASS","DUPLICATE") -> PASS | N14: =CRAWL_LOG!B14 -> Hoàn thành có lỗi | O14: Supplementary panel
A15: 46269 | B15: Thứ Sáu | C15: Official | D15: 00:30 | E15: 46289 | F15: 46292 | G15: 46296 | H15: 46281 | I15: 46411 | J15: =MIN(E15:I15)-A15 -> 12 | K15: =MAX(E15:I15)-A15 -> 142 | L15: =IF(AND(COUNT(E15:I15)=5,MIN(E15:I15)>=A15,E15<>F15,E15<>G15,E15<>H15,E15<>I15,F15<>G15,F15<>H15,F15<>I15,G15<>H15,G15<>I15,H15<>I15),"PASS","CHECK") -> PASS | M15: =IF(COUNTIF(LOCAL_REFERENCE!$D15:$O15,E15)+COUNTIF(LOCAL_REFERENCE!$D15:$O15,F15)+COUNTIF(LOCAL_REFERENCE!$D15:$O15,G15)+COUNTIF(LOCAL_REFERENCE!$D15:$O15,H15)+COUNTIF(LOCAL_REFERENCE!$D15:$O15,I15)=0,"PASS","DUPLICATE") -> PASS | N15: =CRAWL_LOG!B15 -> Hoàn thành có lỗi | O15: Supplementary panel
... A102: 46356 | B102: Thứ Hai | C102: Official | D102: 00:30 | E102: 46373 | F102: 46376 | G102: 46380 | H102: 46365 | I102: 46411 | J102: =MIN(E102:I102)-A102 -> 9 | K102: =MAX(E102:I102)-A102 -> 55 | L102: =IF(AND(COUNT(E102:I102)=5,MIN(E102:I102)>=A102,E102<>F102,E102<>G102,E102<>H102,E102<>I102,F102<>G102,F102<>H102,F102<>I102,G102<>H102,G102<>I102,H102<>I102),"PASS","CHECK") -> PASS | M102: =IF(COUNTIF(LOCAL_REFERENCE!$D102:$O102,E102)+COUNTIF(LOCAL_REFERENCE!$D102:$O102,F102)+COUNTIF(LOCAL_REFERENCE!$D102:$O102,G102)+COUNTIF(LOCAL_REFERENCE!$D102:$O102,H102)+COUNTIF(LOCAL_REFERENCE!$D102:$O102,I102)=0,"PASS","DUPLICATE") -> PASS | N102: =CRAWL_LOG!B102 -> Chưa chạy | O102: Supplementary panel

Sheet CRAWL_LOG
A1: VPS CRAWL LOG — MỖI NGÀY MỘT DÒNG
A2: Ghi một dòng cho mỗi crawl date. Từ 03/09/2026, VPS dùng 354 khách sạn × 5 check-in = 1.770 item dự kiến; các run cũ giữ số item thực tế; không lưu HTML nếu không cần kiểm tra.
A3: Crawl date | B3: Status | C3: Run IDs | D3: Started at | E3: Finished at | F3: Duration (hours) | G3: Total items | H3: Processed | I3: Success | J3: Partial | K3: Sold out | L3: Not bookable | M3: Error | N3: Valid records | O3: Check-in count | P3: Environment | Q3: Notes
A4: 46258 | B4: Hoàn thành | C4: 1 | D4: 46258.026 | E4: 46258.717 | F4: =IF(OR(D4="",E4=""),"",24*(E4-D4)) -> 16.584444 | G4: 1775 | H4: 1775 | I4: 1525 | J4: 0 | K4: 245 | L4: 5 | M4: 0 | N4: 13709 | O4: 5 | P4: vps
A5: 46259 | B5: Hoàn thành | C5: =C4+1 -> 2 | D5: 46259.035 | E5: 46259.754 | F5: =IF(OR(D5="",E5=""),"",24*(E5-D5)) -> 17.253333 | G5: 1775 | H5: 1775 | I5: 1515 | J5: 0 | K5: 255 | L5: 5 | M5: 0 | N5: 13327 | O5: 5 | P5: vps
A6: 46260 | B6: Hoàn thành | C6: 3 | D6: 46260.028 | E6: 46260.774 | F6: 17.901667 | G6: 1775 | H6: 1775 | I6: 1506 | J6: 0 | K6: 264 | L6: 5 | M6: 0 | N6: 13245 | O6: 5 | P6: vps
A7: 46261 | B7: Hoàn thành có lỗi | C7: 4 | D7: 46261.023 | E7: 46261.933 | F7: 21.835 | G7: 1775 | H7: 1775 | I7: 1544 | J7: 0 | K7: 186 | L7: 35 | M7: 10 | N7: 14080 | O7: 5 | P7: vps | Q7: Lấy đúng 1 ngày 03/09 còn lại sai
A8: 46262 | B8: Hoàn thành có lỗi | C8: 5 | D8: 46262.037 | E8: 46262.857 | F8: 19.678333 | G8: 1775 | H8: 1775 | I8: 1495 | J8: 0 | K8: 235 | L8: 40 | M8: 5 | N8: 13016 | O8: 5 | P8: vps
A9: 46263 | B9: Hoàn thành có lỗi | C9: 6 | D9: 46262.732 | E9: 46263.909 | F9: 28.2425 | G9: 1775 | H9: 1775 | I9: 1569 | J9: 0 | K9: 166 | L9: 35 | M9: 5 | N9: 15195 | O9: 5 | P9: vps | Q9: Lấy đúng 2 ngày 24/09, 24/01 còn lại sai
A10: 46264 | B10: Hoàn thành có lỗi | C10: 7 | D10: 46263.732 | E10: 46264.508 | F10: 18.613333 | G10: 1775 | H10: 1775 | I10: 1475 | J10: 0 | K10: 265 | L10: 30 | M10: 5 | N10: 12987 | O10: 5 | P10: vps
A11: 46265 | B11: Hoàn thành có lỗi | C11: 8 | D11: 46264.732 | E11: 46265.57 | F11: 20.127778 | G11: 1775 | H11: 1775 | I11: 1569 | J11: 0 | K11: 171 | L11: 30 | M11: 5 | N11: 15130 | O11: 5 | P11: vps | Q11: Lấy đúng 3 ngày 24/09, 27/09, 24/01 còn lại sai
A12: 46266 | B12: Hoàn thành có lỗi | C12: 9 | D12: 46265.732 | E12: 46266.582 | F12: 20.396389 | G12: 1775 | H12: 1775 | I12: 1578 | J12: 0 | K12: 162 | L12: 30 | M12: 5 | N12: 15196 | O12: 5 | P12: vps | Q12: Lấy đúng 3 ngày 24/09, 27/09, 24/01 còn lại sai
A13: 46267 | B13: Hoàn thành có lỗi | C13: 10 | D13: 46267.023 | E13: 46267.89 | F13: 20.808056 | G13: 1775 | H13: 1775 | I13: 1580 | J13: 0 | K13: 160 | L13: 30 | M13: 5 | N13: 12932 | O13: 5 | P13: vps | Q13: Lấy đúng 3 ngày 24/09, 27/09, 24/01 còn lại sai
A14: 46268 | B14: Hoàn thành có lỗi | C14: 13 | D14: 46268.024 | E14: 46268.803 | F14: 18.680556 | G14: 1770 | H14: 1770 | I14: 1575 | J14: 0 | K14: 165 | L14: 20 | M14: 10 | N14: 14827 | O14: 5 | P14: vps | Q14: Lấy đúng 3 ngày 24/09, 27/09, 24/01 còn lại sai
A15: 46269 | B15: Hoàn thành có lỗi | C15: 14 | D15: 46269.024 | E15: 46269.91 | F15: 21.270278 | G15: 1770 | H15: 1770 | I15: 1578 | J15: 0 | K15: 167 | L15: 15 | M15: 10 | N15: 14967 | O15: 5 | P15: vps | Q15: Lấy đúng 4 ngày 24/09, 27/09, 01/10, 24/01
A16: 46270 | B16: Hoàn thành có lỗi | C16: 15 | D16: 46151.023 | E16: 46270.939 | F16: 21.981944 | G16: 1770 | H16: 1770 | I16: 1583 | J16: 0 | K16: 162 | L16: 15 | M16: 10 | N16: 14706 | O16: 5 | P16: vps
A17: 46271 | B17: Hoàn thành có lỗi | C17: 16 | D17: 46271.025 | E17: 46271.98 | F17: 22.927778 | G17: 1770 | H17: 1770 | I17: 1584 | J17: 0 | K17: 161 | L17: 15 | M17: 10 | N17: 14816 | O17: 5 | P17: vps
A18: 46272 | B18: Hoàn thành có lỗi | C18: 17 | D18: 46272.023 | E18: 46272.931 | F18: 21.795 | G18: 1770 | H18: 1770 | I18: 1581 | J18: 0 | K18: 159 | L18: 20 | M18: 10 | N18: 14688 | O18: 5 | P18: vps
A19: 46273 | B19: Hoàn thành có lỗi | C19: 18 | D19: 46273.024 | E19: 46273.966 | F19: 22.610278 | G19: 1770 | H19: 1770 | I19: 1582 | J19: 0 | K19: 158 | L19: 20 | M19: 10 | N19: 15259 | O19: 5 | P19: vps
A20: 46274 | B20: Hoàn thành có lỗi | C20: 19 | D20: 46274.023 | E20: 46274.926 | F20: 21.653056 | G20: 1770 | H20: 1770 | I20: 1574 | J20: 0 | K20: 166 | L20: 20 | M20: 10 | N20: 15038 | O20: 5 | P20: vps
A21: 46275 | B21: Hoàn thành có lỗi | C21: 20 | D21: 46275.03 | E21: 46275.94 | F21: 21.846111 | G21: 1770 | H21: 1770 | I21: 1569 | J21: 0 | K21: 166 | L21: 25 | M21: 10 | N21: 14673 | O21: 5 | P21: vps
A22: 46276 | B22: Hoàn thành có lỗi | C22: 21 | D22: 46276.026 | E22: 46276.945 | F22: 22.067222 | G22: 1770 | H22: 1770 | I22: 1579 | J22: 0 | K22: 166 | L22: 15 | M22: 10 | N22: 14887 | O22: 5 | P22: vps
A23: 46277 | B23: Hoàn thành có lỗi | C23: 22 | D23: 46277.046 | E23: 46277.988 | F23: 22.610556 | G23: 1770 | H23: 1770 | I23: 1578 | J23: 0 | K23: 167 | L23: 15 | M23: 10 | N23: 14760 | O23: 5 | P23: vps
A24: 46278 | B24: Hoàn thành có lỗi | C24: 23 | D24: 46278.031 | E24: 46278.994 | F24: =IF(OR(D24="",E24=""),"",24*(E24-D24)) -> 23.093333 | G24: 1770 | H24: 1770 | I24: 1581 | J24: 0 | K24: 160 | L24: 15 | M24: 14 | N24: 14508 | O24: 5 | P24: vps
A25: 46279 | B25: Hoàn thành có lỗi | C25: 24 | D25: 46279.019 | E25: 46279.882 | F25: =IF(OR(D25="",E25=""),"",24*(E25-D25)) -> 20.702222 | G25: 1770 | H25: 1770 | I25: 1654 | J25: 0 | K25: 91 | L25: 15 | M25: 10 | N25: 15208 | O25: 5 | P25: vps | Q25: Lấy đúng 2 ngày 27/09, 01/10
A26: 46280 | B26: Hoàn thành có lỗi | C26: 25 | D26: 46280.024 | E26: 46280.913 | F26: =IF(OR(D26="",E26=""),"",24*(E26-D26)) -> 21.353889 | G26: 1770 | H26: 1770 | I26: 1572 | J26: 0 | K26: 168 | L26: 20 | M26: 10 | N26: 14392 | O26: 5 | P26: vps
A27: 46281 | B27: Hoàn thành có lỗi | C27: 26 | D27: 46281.025 | E27: 46281.856 | F27: =IF(OR(D27="",E27=""),"",24*(E27-D27)) -> 19.938333 | G27: 1770 | H27: 1770 | I27: 1559 | J27: 0 | K27: 181 | L27: 20 | M27: 10 | N27: 13640 | O27: 5 | P27: vps
A28: 46282 | B28: Hoàn thành có lỗi | C28: 27 | D28: 46282.021 | E28: 46282.867 | F28: =IF(OR(D28="",E28=""),"",24*(E28-D28)) -> 20.308889 | G28: 1770 | H28: 1770 | I28: 1555 | J28: 0 | K28: 160 | L28: 45 | M28: 10 | N28: 14754 | O28: 5 | P28: vps | Q28: Run ID 27; deploy: manual; artifact không lưu; scraper_version=2.3.0
A29: 46283 | B29: Hoàn thành có lỗi | C29: 28 | D29: 2026-09-18 00:31:00 | E29: 2026-09-18 21:20:32 | F29: =IF(OR(D29="",E29=""),"",24*(E29-D29)) -> 20.825556 | G29: 1770 | H29: 1770 | I29: 1562 | J29: 0 | K29: 158 | L29: 40 | M29: 10 | N29: 14371 | O29: 5 | P29: vps | Q29: Run ID 28; deploy: manual; artifact không lưu; scraper_version=2.3.0
A30: 46284 | B30: Hoàn thành có lỗi | C30: 29 | D30: 2026-09-19 00:30:55 | E30: 2026-09-20 20:23:53 | F30: =IF(OR(D30="",E30=""),"",24*(E30-D30)) -> 43.882778 | G30: 1770 | H30: 1770 | I30: 1573 | J30: 0 | K30: 167 | L30: 20 | M30: 10 | N30: 14607 | O30: 5 | P30: vps | Q30: thực tế là do bị lỗi proxy nên kéo dài tới tận hôm sau để chạy lại
A31: 46285 | B31: Thất bại | F31: =IF(OR(D31="",E31=""),"",24*(E31-D31)) | O31: 5 | P31: vps
A32: 46286 | B32: Hoàn thành có lỗi | C32: 31 | D32: 46286.029 | E32: 46286.694 | F32: =IF(OR(D32="",E32=""),"",24*(E32-D32)) -> 15.9675 | G32: 1770 | H32: 1770 | I32: 1568 | J32: 0 | K32: 172 | L32: 20 | M32: 10 | N32: 14071 | O32: 5 | P32: vps | Q32: Run ID 31; deploy VPS; artifact không lưu; scraper_version 2.3.0
A33: 46287 | B33: Hoàn thành có lỗi | C33: 32 | D33: 46287.022 | E33: 46287.707 | F33: =IF(OR(D33="",E33=""),"",24*(E33-D33)) -> 16.449167 | G33: 1770 | H33: 1770 | I33: 1555 | J33: 0 | K33: 185 | L33: 20 | M33: 10 | N33: 13934 | O33: 5 | P33: vps | Q33: Run ID 32; deploy VPS; artifact không lưu; scraper_version 2.3.0
A34: 46288 | B34: Hoàn thành có lỗi | C34: 33 | D34: 46288.023 | E34: 46288.717 | F34: =IF(OR(D34="",E34=""),"",24*(E34-D34)) -> 16.638056 | G34: 1770 | H34: 1770 | I34: 1558 | J34: 0 | K34: 187 | L34: 15 | M34: 10 | N34: 13802 | O34: 5 | P34: vps | Q34: Run ID 33; deploy VPS; artifact không lưu; scraper_version 2.3.0
A35: 46289 | B35: Hoàn thành có lỗi | C35: 34 | D35: 46289.022 | E35: 46289.691 | F35: =IF(OR(D35="",E35=""),"",24*(E35-D35)) -> 16.061389 | G35: 1770 | H35: 1770 | I35: 1505 | J35: 0 | K35: 235 | L35: 20 | M35: 10 | N35: 13008 | O35: 5 | P35: vps | Q35: Run ID 34; deploy VPS; artifact không lưu; scraper_version 2.3.0
A36: 46290 | B36: Hoàn thành có lỗi | C36: 35 | D36: 46290.027 | E36: 46290.663 | F36: =IF(OR(D36="",E36=""),"",24*(E36-D36)) -> 15.249722 | G36: 1770 | H36: 1770 | I36: 1527 | J36: 0 | K36: 213 | L36: 20 | M36: 10 | N36: 13661 | O36: 5 | P36: vps | Q36: Run ID 35; deploy VPS; artifact không lưu; scraper_version 2.3.0
A37: 46291 | B37: Hoàn thành có lỗi | C37: 36 | D37: 46291.026 | E37: 46291.672 | F37: =IF(OR(D37="",E37=""),"",24*(E37-D37)) -> 15.49 | G37: 1770 | H37: 1770 | I37: 1526 | J37: 0 | K37: 189 | L37: 45 | M37: 10 | N37: 13951 | O37: 5 | P37: vps | Q37: Run ID 36; deploy VPS; artifact không lưu; scraper_version 2.3.0
A38: 46292 | B38: Hoàn thành có lỗi | C38: 37 | D38: 2026-09-27 00:33:05 | E38: 2026-09-27 16:20:08 | F38: =IF(OR(D38="",E38=""),"",24*(E38-D38)) -> 15.784167 | G38: 1770 | H38: 1770 | I38: 1519 | J38: 0 | K38: 191 | L38: 50 | M38: 10 | N38: 13247 | O38: 5 | P38: vps | Q38: Run ID 37; deploy VPS; artifact không lưu; scraper_version 2.3.0
A39: 46293 | B39: Hoàn thành có lỗi | C39: 38 | D39: 46292.744 | E39: 46293.412 | F39: =IF(OR(D39="",E39=""),"",24*(E39-D39)) -> 16.0425 | G39: 1770 | H39: 1770 | I39: 1506 | J39: 0 | K39: 204 | L39: 50 | M39: 10 | N39: 13998 | O39: 5 | P39: vps | Q39: Run ID 38, deploy VPS, artifact không lưu, scraper_version 2.3.0
A40: 46294 | B40: Hoàn thành có lỗi | C40: 39 | D40: 46294.02 | E40: 46294.678 | F40: =IF(OR(D40="",E40=""),"",24*(E40-D40)) -> 15.783333 | G40: 1770 | H40: 1770 | I40: 1511 | J40: 0 | K40: 204 | L40: 40 | M40: 15 | N40: 14467 | O40: 5 | P40: vps | Q40: Run ID 39, deploy VPS, artifact không lưu, scraper_version 2.3.0
...

Sheet LOCAL_REFERENCE
A1: LOCAL REFERENCE — 12 CHECK-IN DÙNG ĐỂ LOẠI TRÙNG
A2: Nguồn: D:/MSE/CAPSTONE/outputs/crawl-data-planner-20260816/crawl_sampling_master.xlsx. Đây là snapshot lịch local tại thời điểm tạo workbook VPS; cập nhật lại file VPS nếu lịch local thay đổi.
A3: Crawl date | B3: Thứ | C3: Start time | D3: N1 | E3: N2 | F3: N3 | G3: N4 | H3: N5 | I3: N6 | J3: N7 | K3: N8 | L3: N9 | M3: F1 | N3: F2 | O3: F3 | P3: Source file
A4: 46258 | B4: Thứ Hai | C4: 00:30 | D4: 46282 | E4: 46284 | F4: 46259 | G4: 46263 | H4: 46267 | I4: 46271 | J4: 46274 | K4: 46277 | L4: 46279 | M4: 46306 | N4: 46344 | O4: 46388 | P4: crawl_sampling_master.xlsx
A5: 46259 | B5: Thứ Ba | C5: 00:30 | D5: 46282 | E5: 46284 | F5: 46259 | G5: 46263 | H5: 46267 | I5: 46271 | J5: 46274 | K5: 46277 | L5: 46279 | M5: 46306 | N5: 46344 | O5: 46388 | P5: crawl_sampling_master.xlsx
A6: 46260 | B6: Thứ Tư | C6: 00:30 | D6: 46282 | E6: 46284 | F6: 46287 | G6: 46263 | H6: 46267 | I6: 46271 | J6: 46274 | K6: 46277 | L6: 46279 | M6: 46306 | N6: 46344 | O6: 46388 | P6: crawl_sampling_master.xlsx
A7: 46261 | B7: Thứ Năm | C7: 00:30 | D7: 46282 | E7: 46284 | F7: 46287 | G7: 46263 | H7: 46267 | I7: 46271 | J7: 46274 | K7: 46277 | L7: 46279 | M7: 46306 | N7: 46344 | O7: 46388 | P7: crawl_sampling_master.xlsx
A8: 46262 | B8: Thứ Sáu | C8: 00:30 | D8: 46282 | E8: 46284 | F8: 46287 | G8: 46263 | H8: 46267 | I8: 46271 | J8: 46274 | K8: 46277 | L8: 46279 | M8: 46306 | N8: 46344 | O8: 46388 | P8: crawl_sampling_master.xlsx
A9: 46263 | B9: Thứ Bảy | C9: 00:30 | D9: 46282 | E9: 46284 | F9: 46287 | G9: 46263 | H9: 46267 | I9: 46271 | J9: 46274 | K9: 46277 | L9: 46279 | M9: 46306 | N9: 46344 | O9: 46388 | P9: crawl_sampling_master.xlsx
A10: 46264 | B10: Chủ Nhật | C10: 00:30 | D10: 46282 | E10: 46284 | F10: 46287 | G10: 46291 | H10: 46267 | I10: 46271 | J10: 46274 | K10: 46277 | L10: 46279 | M10: 46306 | N10: 46344 | O10: 46388 | P10: crawl_sampling_master.xlsx
A11: 46265 | B11: Thứ Hai | C11: 00:30 | D11: 46282 | E11: 46284 | F11: 46287 | G11: 46291 | H11: 46267 | I11: 46271 | J11: 46274 | K11: 46277 | L11: 46279 | M11: 46306 | N11: 46344 | O11: 46388 | P11: crawl_sampling_master.xlsx
A12: 46266 | B12: Thứ Ba | C12: 00:30 | D12: 46282 | E12: 46284 | F12: 46287 | G12: 46291 | H12: 46267 | I12: 46271 | J12: 46274 | K12: 46277 | L12: 46279 | M12: 46306 | N12: 46344 | O12: 46388 | P12: crawl_sampling_master.xlsx
A13: 46267 | B13: Thứ Tư | C13: 00:30 | D13: 46282 | E13: 46284 | F13: 46287 | G13: 46291 | H13: 46267 | I13: 46271 | J13: 46274 | K13: 46277 | L13: 46279 | M13: 46306 | N13: 46344 | O13: 46388 | P13: crawl_sampling_master.xlsx
A14: 46268 | B14: Thứ Năm | C14: 00:30 | D14: 46282 | E14: 46284 | F14: 46287 | G14: 46291 | H14: 46295 | I14: 46271 | J14: 46274 | K14: 46277 | L14: 46279 | M14: 46306 | N14: 46344 | O14: 46388 | P14: crawl_sampling_master.xlsx
A15: 46269 | B15: Thứ Sáu | C15: 00:30 | D15: 46282 | E15: 46284 | F15: 46287 | G15: 46291 | H15: 46295 | I15: 46271 | J15: 46274 | K15: 46277 | L15: 46279 | M15: 46306 | N15: 46344 | O15: 46388 | P15: crawl_sampling_master.xlsx
... A102: 46356 | B102: Thứ Hai | C102: 00:30 | D102: 46366 | E102: 46368 | F102: 46371 | G102: 46375 | H102: 46379 | I102: 46383 | J102: 46358 | K102: 46361 | L102: 46363 | M102: 46362 | N102: 46428 | O102: 46388 | P102: crawl_sampling_master.xlsx

Sheet SLOT_RULES
A1: QUY TẮC 5 SLOT VPS BỔ SUNG
A3: Slot | B3: Vai trò | C3: Mục đích | D3: Chuỗi anchor | E3: Điều kiện roll | F3: Kiểm tra bắt buộc
A4: V1 weekday | B4: Ngày thường bổ sung | C4: Bổ sung observation ngày thường nằm giữa các anchor local | D4: 27/08/2026 → 24/09/2026 → 22/10/2026 → 19/11/2026 → 17/12/2026 | E4: Giữ nguyên đến hết ngày check-in; roll từ ngày hôm sau hoặc khi trùng local | F4: Ngày >= crawl date; khác 4 slot VPS; không thuộc 12 slot local
A5: V2 weekend | B5: Cuối tuần bổ sung | C5: Bổ sung observation cuối tuần không trùng chuỗi near của local | D5: 30/08/2026 → 27/09/2026 → 25/10/2026 → 22/11/2026 → 20/12/2026 | E5: Giữ nguyên đến hết ngày check-in; roll từ ngày hôm sau hoặc khi trùng local | F5: Ngày >= crawl date; khác 4 slot VPS; không thuộc 12 slot local
A6: V3 seasonal | B6: Ngày mùa vụ/đối chứng | C6: Theo dõi ngày liền kề mùa vụ hoặc sự kiện để so với ngày lõi | D6: 03/09/2026 → 01/10/2026 → 29/10/2026 → 26/11/2026 → 24/12/2026 | E6: Giữ nguyên đến hết ngày check-in; roll từ ngày hôm sau hoặc khi trùng local | F6: Ngày >= crawl date; khác 4 slot VPS; không thuộc 12 slot local
A7: V4 medium | B7: Khoảng trung hạn | C7: Lấp khoảng lead time trung hạn còn thưa trong lịch local | D7: 16/09/2026 → 14/10/2026 → 11/11/2026 → 09/12/2026 → 06/01/2027 | E7: Giữ nguyên đến hết ngày check-in; roll từ ngày hôm sau hoặc khi trùng local | F7: Ngày >= crawl date; khác 4 slot VPS; không thuộc 12 slot local
A8: V5 long | B8: Anchor dài hạn | C8: Theo dõi một ngày xa cố định để tạo chuỗi giảm lead time dài | D8: 24/01/2027 → 24/04/2027 | E8: Giữ nguyên đến hết ngày check-in; roll từ ngày hôm sau hoặc khi trùng local | F8: Ngày >= crawl date; khác 4 slot VPS; không thuộc 12 slot local
A10: Quy tắc chung | B10: Không random hằng ngày | C10: Năm ngày phải tạo chuỗi observation lặp lại theo thời gian
A11: Lead time 0 | B11: Hợp lệ | C11: Slot chỉ roll khi check-in < crawl date
A12: Thay đổi local | B12: Tạo lại lịch VPS | C12: LOCAL_REFERENCE là snapshot; nếu lịch local đổi thì phải tái sinh workbook VPS

Sheet README
A1: HƯỚNG DẪN SỬ DỤNG LỊCH CRAWL VPS
A3: Bước | B3: Thao tác | C3: Kết quả mong đợi | D3: Lưu ý
A4: 1 | B4: Mở sheet VPS_CRAWL_PLAN và tìm Crawl date hôm nay | C4: Có đúng 5 ngày check-in | D4: Hai cột kiểm tra phải đều PASS
A5: 2 | B5: Mở web scraper đã deploy trên VPS | C5: Trang nhập file và ngày check-in sẵn sàng | D5: Đây là thao tác thủ công qua web
A6: 3 | B6: Upload link_hotel_data_expanded.xlsx | C6: 354 khách sạn hợp lệ | D6: Dùng cùng file nguồn với local
A7: 4 | B7: Chọn đúng V1–V5 của ngày crawl | C7: Không trùng 12 ngày local | D7: Không tự thay ngày nếu chưa cập nhật workbook
A8: 5 | B8: Bắt đầu cào và theo dõi run | C8: Khoảng 1.770 item được tạo | D8: Không cần lưu HTML nếu chỉ thu thập dataset
A9: 6 | B9: Khi kết thúc, cập nhật CRAWL_LOG | C9: Có thời gian, số run và aggregate | D9: Hoàn thành có lỗi vẫn phải ghi số liệu
A10: 7 | B10: Nếu lịch local thay đổi | C10: Tạo lại workbook VPS từ local mới | D10: Không sửa LOCAL_REFERENCE bằng tay
