Workbook

Sheet SUMMARY
A1: LỊCH CRAWL HẰNG NGÀY — 18/08/2026 ĐẾN 30/11/2026
A3: Thông số | B3: Giá trị | D3: Kiểm tra | E3: Kết quả
A4: Ngày bắt đầu | B4: 46252 | D4: Số ngày mong đợi | E4: 105
A5: Ngày kết thúc | B5: 46356 | D5: Số dòng lịch thực tế | E5: =B8
A6: Giờ bắt đầu mỗi ngày | B6: 00:30 | D6: Mỗi ngày đủ 12 check-in | E6: =IF(COUNTIF('DAILY_CRAWL_PLAN'!$S$4:$S$108,"PASS")=105,"PASS","CHECK")
A7: Múi giờ | B7: Asia/Ho_Chi_Minh | D7: Trạng thái workbook | E7: =IF(AND(E4=E5,E6="PASS"),"PASS","CHECK")
A8: Tổng số ngày theo lịch | B8: =COUNTA('DAILY_CRAWL_PLAN'!$A$4:$A$108)
A9: Đã hoàn thành | B9: =COUNTIF('CRAWL_LOG'!$C$4:$C$108,"Hoàn thành")
A10: Hoàn thành có lỗi | B10: =COUNTIF('CRAWL_LOG'!$C$4:$C$108,"Hoàn thành có lỗi")
A11: Đang chạy | B11: =COUNTIF('CRAWL_LOG'!$C$4:$C$108,"Đang chạy")
A12: Chưa chạy | B12: =COUNTIF('CRAWL_LOG'!$C$4:$C$108,"Chưa chạy")
A15: Mỗi ngày có 9 check-in gần + 3 check-in xa; lead time 0 (check-in đúng ngày crawl) là hợp lệ và slot chỉ roll từ ngày hôm sau.

Sheet DAILY_CRAWL_PLAN
A1: DAILY CRAWL PLAN — 105 NGÀY, 12 CHECK-IN MỖI NGÀY
A2: N1–N9 là slot gần; F1–F3 là slot xa. Check-in có thể trùng ngày crawl (lead time 0), không được ở quá khứ; checkout = check-in + 1 ngày.
A3: Crawl date | B3: Thứ | C3: Phase | D3: Start time (ICT) | E3: N1 gần | F3: N2 gần | G3: N3 gần | H3: N4 gần | I3: N5 gần | J3: N6 gần | K3: N7 gần | L3: N8 gần | M3: N9 gần | N3: F1 xa | O3: F2 xa | P3: F3 xa | Q3: Min lead | R3: Max lead | S3: 12 ngày hợp lệ | T3: Crawl status | U3: Event flags | V3: Automation note
A4: 46252 | B4: Thứ Ba | C4: Warm-up | D4: 00:30 | E4: 46254 | F4: 46256 | G4: 46259 | H4: 46263 | I4: 46267 | J4: 46271 | K4: 46274 | L4: 46277 | M4: 46279 | N4: 46306 | O4: 46344 | P4: 46388 | Q4: 2 | R4: 136 | S4: PASS | T4: ='CRAWL_LOG'!C4 | U4: Có Quốc khánh 02/09; Có Tết Dương lịch 01/01
A5: 46253 | B5: Thứ Tư | C5: Warm-up | D5: 00:30 | E5: 46254 | F5: 46256 | G5: 46259 | H5: 46263 | I5: 46267 | J5: 46271 | K5: 46274 | L5: 46277 | M5: 46279 | N5: 46306 | O5: 46344 | P5: 46388 | Q5: 1 | R5: 135 | S5: PASS | T5: ='CRAWL_LOG'!C5 | U5: Có Quốc khánh 02/09; Có Tết Dương lịch 01/01
A6: 46254 | B6: Thứ Năm | C6: Warm-up | D6: 00:30 | E6: 46254 | F6: 46256 | G6: 46259 | H6: 46263 | I6: 46267 | J6: 46271 | K6: 46274 | L6: 46277 | M6: 46279 | N6: 46306 | O6: 46344 | P6: 46388 | Q6: 0 | R6: 134 | S6: PASS | T6: ='CRAWL_LOG'!C6 | U6: Có Quốc khánh 02/09; Có Tết Dương lịch 01/01
A7: 46255 | B7: Thứ Sáu | C7: Warm-up | D7: 00:30 | E7: 46282 | F7: 46256 | G7: 46259 | H7: 46263 | I7: 46267 | J7: 46271 | K7: 46274 | L7: 46277 | M7: 46279 | N7: 46306 | O7: 46344 | P7: 46388 | Q7: 1 | R7: 133 | S7: PASS | T7: ='CRAWL_LOG'!C7 | U7: Có Quốc khánh 02/09; Có Tết Dương lịch 01/01
A8: 46256 | B8: Thứ Bảy | C8: Warm-up | D8: 00:30 | E8: 46282 | F8: 46256 | G8: 46259 | H8: 46263 | I8: 46267 | J8: 46271 | K8: 46274 | L8: 46277 | M8: 46279 | N8: 46306 | O8: 46344 | P8: 46388 | Q8: 0 | R8: 132 | S8: PASS | T8: ='CRAWL_LOG'!C8 | U8: Có Quốc khánh 02/09; Có Tết Dương lịch 01/01
A9: 46257 | B9: Chủ Nhật | C9: Warm-up | D9: 00:30 | E9: 46282 | F9: 46284 | G9: 46259 | H9: 46263 | I9: 46267 | J9: 46271 | K9: 46274 | L9: 46277 | M9: 46279 | N9: 46306 | O9: 46344 | P9: 46388 | Q9: 2 | R9: 131 | S9: PASS | T9: ='CRAWL_LOG'!C9 | U9: Có Quốc khánh 02/09; Có Tết Dương lịch 01/01
A10: 46258 | B10: Thứ Hai | C10: Warm-up | D10: 00:30 | E10: 46282 | F10: 46284 | G10: 46259 | H10: 46263 | I10: 46267 | J10: 46271 | K10: 46274 | L10: 46277 | M10: 46279 | N10: 46306 | O10: 46344 | P10: 46388 | Q10: 1 | R10: 130 | S10: PASS | T10: ='CRAWL_LOG'!C10 | U10: Có Quốc khánh 02/09; Có Tết Dương lịch 01/01
A11: 46259 | B11: Thứ Ba | C11: Warm-up | D11: 00:30 | E11: 46282 | F11: 46284 | G11: 46259 | H11: 46263 | I11: 46267 | J11: 46271 | K11: 46274 | L11: 46277 | M11: 46279 | N11: 46306 | O11: 46344 | P11: 46388 | Q11: 0 | R11: 129 | S11: PASS | T11: ='CRAWL_LOG'!C11 | U11: Có Quốc khánh 02/09; Có Tết Dương lịch 01/01
A12: 46260 | B12: Thứ Tư | C12: Warm-up | D12: 00:30 | E12: 46282 | F12: 46284 | G12: 46287 | H12: 46263 | I12: 46267 | J12: 46271 | K12: 46274 | L12: 46277 | M12: 46279 | N12: 46306 | O12: 46344 | P12: 46388 | Q12: 3 | R12: 128 | S12: PASS | T12: ='CRAWL_LOG'!C12 | U12: Có Quốc khánh 02/09; Có Tết Dương lịch 01/01
A13: 46261 | B13: Thứ Năm | C13: Warm-up | D13: 00:30 | E13: 46282 | F13: 46284 | G13: 46287 | H13: 46263 | I13: 46267 | J13: 46271 | K13: 46274 | L13: 46277 | M13: 46279 | N13: 46306 | O13: 46344 | P13: 46388 | Q13: 2 | R13: 127 | S13: PASS | T13: ='CRAWL_LOG'!C13 | U13: Có Quốc khánh 02/09; Có Tết Dương lịch 01/01
A14: 46262 | B14: Thứ Sáu | C14: Warm-up | D14: 00:30 | E14: 46282 | F14: 46284 | G14: 46287 | H14: 46263 | I14: 46267 | J14: 46271 | K14: 46274 | L14: 46277 | M14: 46279 | N14: 46306 | O14: 46344 | P14: 46388 | Q14: 1 | R14: 126 | S14: PASS | T14: ='CRAWL_LOG'!C14 | U14: Có Quốc khánh 02/09; Có Tết Dương lịch 01/01
A15: 46263 | B15: Thứ Bảy | C15: Warm-up | D15: 00:30 | E15: 46282 | F15: 46284 | G15: 46287 | H15: 46263 | I15: 46267 | J15: 46271 | K15: 46274 | L15: 46277 | M15: 46279 | N15: 46306 | O15: 46344 | P15: 46388 | Q15: 0 | R15: 125 | S15: PASS | T15: ='CRAWL_LOG'!C15 | U15: Có Quốc khánh 02/09; Có Tết Dương lịch 01/01
... A108: 46356 | B108: Thứ Hai | C108: Official | D108: 00:30 | E108: 46366 | F108: 46368 | G108: 46371 | H108: 46375 | I108: 46379 | J108: 46383 | K108: 46358 | L108: 46361 | M108: 46363 | N108: 46362 | O108: 46428 | P108: 46388 | Q108: 2 | R108: 72 | S108: PASS | T108: ='CRAWL_LOG'!C108 | U108: Có Tết Dương lịch 01/01

Sheet CRAWL_LOG
A1: CRAWL LOG — MỖI NGÀY CÀO CHỈ MỘT DÒNG
A2: Nếu backend chia nhiều batch/run, ghi toàn bộ run ID vào cùng một ô Run IDs; không thêm dòng mới cho cùng crawl date.
A3: Crawl date | B3: Start time (ICT) | C3: Status | D3: Run IDs | E3: Started at | F3: Finished at | G3: Duration (hours) | H3: Total items | I3: Processed | J3: Success | K3: Partial | L3: Sold out | M3: Not bookable | N3: Error | O3: Valid records | P3: Check-in count | Q3: Notes
A4: 46252 | B4: 00:30 | C4: Hoàn thành | D4: 11 | E4: 46252.022 | F4: 46252.721 | G4: =IF(OR(E4="",F4=""),"",(F4-E4)*24) | H4: 4260 | I4: 4260 | J4: 3815 | K4: 0 | L4: 433 | M4: 12 | N4: 0 | O4: 41218 | P4: 12 | Q4: Scheduled run 11 đã đạt terminal state
A5: 46253 | B5: 00:30 | C5: Hoàn thành | D5: 12 | E5: 46253.022 | F5: 46253.724 | G5: =IF(OR(E5="",F5=""),"",(F5-E5)*24) | H5: 4260 | I5: 4260 | J5: 3816 | K5: 0 | L5: 444 | M5: 0 | N5: 0 | O5: 39507 | P5: 12 | Q5: Scheduled run 12 đã đạt terminal state
A6: 46254 | B6: 00:30 | C6: Hoàn thành | D6: 14 | E6: 46254.044 | F6: 46254.73 | G6: =IF(OR(E6="",F6=""),"",(F6-E6)*24) | H6: 4260 | I6: 4260 | J6: 3785 | K6: 0 | L6: 463 | M6: 12 | N6: 0 | O6: 39339 | P6: 12 | Q6: Scheduled run 14 đã đạt terminal state
A7: 46255 | B7: 00:30 | C7: Hoàn thành | D7: 16 | E7: 46255.075 | F7: 46255.906 | G7: =IF(OR(E7="",F7=""),"",(F7-E7)*24) | H7: 4260 | I7: 4260 | J7: 3808 | K7: 0 | L7: 452 | M7: 0 | N7: 0 | O7: 34030 | P7: 12 | Q7: Scheduled run 16 đã đạt terminal state
A8: 46256 | B8: 00:30 | C8: Hoàn thành | D8: 17 | E8: 46256.027 | F8: 46256.698 | G8: =IF(OR(E8="",F8=""),"",(F8-E8)*24) | H8: 4260 | I8: 4260 | J8: 3782 | K8: 0 | L8: 478 | M8: 0 | N8: 0 | O8: 34252 | P8: 12 | Q8: Scheduled run 17 đã đạt terminal state
A9: 46257 | B9: 00:30 | C9: Hoàn thành | D9: 18 | E9: 46257.022 | F9: 46257.721 | G9: =IF(OR(E9="",F9=""),"",(F9-E9)*24) | H9: 4260 | I9: 4260 | J9: 3818 | K9: 0 | L9: 430 | M9: 12 | N9: 0 | O9: 34674 | P9: 12 | Q9: Scheduled run 18 đã đạt terminal state
A10: 46258 | B10: 00:30 | C10: Hoàn thành | D10: 20 | E10: 46258.034 | F10: 46258.716 | G10: =IF(OR(E10="",F10=""),"",(F10-E10)*24) | H10: 4260 | I10: 4260 | J10: 3821 | K10: 0 | L10: 427 | M10: 12 | N10: 0 | O10: 34218 | P10: 12 | Q10: Scheduled run 20 đã đạt terminal state
A11: 46259 | B11: 00:30 | C11: Hoàn thành | D11: 21 | E11: 46259.022 | F11: 46259.696 | G11: =IF(OR(E11="",F11=""),"",(F11-E11)*24) | H11: 4260 | I11: 4260 | J11: 3811 | K11: 0 | L11: 437 | M11: 12 | N11: 0 | O11: 34746 | P11: 12 | Q11: Scheduled run 21 đã đạt terminal state
A12: 46260 | B12: 00:30 | C12: Hoàn thành | D12: 22 | E12: 46260.023 | F12: 46260.699 | G12: =IF(OR(E12="",F12=""),"",(F12-E12)*24) | H12: 4260 | I12: 4260 | J12: 3816 | K12: 0 | L12: 432 | M12: 12 | N12: 0 | O12: 34961 | P12: 12 | Q12: Scheduled run 22 đã đạt terminal state
A13: 46261 | B13: 00:30 | C13: Hoàn thành có lỗi | D13: 23 | E13: 46261.022 | F13: 46261.772 | G13: =IF(OR(E13="",F13=""),"",(F13-E13)*24) | H13: 4260 | I13: 4260 | J13: 3747 | K13: 0 | L13: 405 | M13: 84 | N13: 24 | O13: 33540 | P13: 12 | Q13: Scheduled run 23 đã đạt terminal state
A14: 46262 | B14: 00:30 | C14: Hoàn thành có lỗi | D14: 24 | E14: 46262.022 | F14: 46262.694 | G14: =IF(OR(E14="",F14=""),"",(F14-E14)*24) | H14: 4260 | I14: 4260 | J14: 3768 | K14: 0 | L14: 384 | M14: 96 | N14: 12 | O14: 34100 | P14: 12 | Q14: Scheduled run 24 đã đạt terminal state
A15: 46263 | B15: 00:30 | C15: Hoàn thành có lỗi | D15: 25 | E15: 46263.022 | F15: 46263.7 | G15: =IF(OR(E15="",F15=""),"",(F15-E15)*24) | H15: 4260 | I15: 4260 | J15: 3755 | K15: 0 | L15: 409 | M15: 84 | N15: 12 | O15: 33683 | P15: 12 | Q15: Scheduled run 25 đã đạt terminal state
... A25: 46273 | B25: 00:30 | C25: Hoàn thành có lỗi | D25: 35 | E25: 46273.022 | F25: 46273.849 | G25: =IF(OR(E25="",F25=""),"",(F25-E25)*24) | H25: 4248 | I25: 4248 | J25: 3842 | K25: 0 | L25: 334 | M25: 48 | N25: 24 | O25: 34326 | P25: 12 | Q25: Scheduled run 35 đã đạt terminal state
A26: 46274 | B26: 00:30 | C26: Hoàn thành có lỗi | D26: 36 | E26: 46274.022 | F26: 46275.165 | G26: =IF(OR(E26="",F26=""),"",(F26-E26)*24) | H26: 4248 | I26: 4248 | J26: 3713 | K26: 0 | L26: 382 | M26: 60 | N26: 93 | O26: 33440 | P26: 12 | Q26: Scheduled run 36 đã đạt terminal state; save_artifacts=false; scraper_version=2.3.0
A27: 46275 | B27: 00:30 | C27: Hoàn thành có lỗi | D27: 37 | E27: 46275.166 | F27: 46275.98 | G27: =IF(OR(E27="",F27=""),"",(F27-E27)*24) | H27: 4248 | I27: 4248 | J27: 3814 | K27: 0 | L27: 361 | M27: 48 | N27: 25 | O27: 34396 | P27: 12 | Q27: Scheduled run 37 đã đạt terminal state; save_artifacts=false; scraper_version=2.3.0
A28: 46276 | B28: 00:30 | C28: Hoàn thành có lỗi | D28: 38 | E28: 46276.023 | F28: 46276.855 | G28: =IF(OR(E28="",F28=""),"",(F28-E28)*24) | H28: 4248 | I28: 4248 | J28: 3822 | K28: 0 | L28: 366 | M28: 36 | N28: 24 | O28: 34224 | P28: 12 | Q28: Scheduled run 38 đã đạt terminal state
A29: 46277 | B29: 00:30 | C29: Hoàn thành có lỗi | D29: 39 | E29: 46277.022 | F29: 46277.68 | G29: =IF(OR(E29="",F29=""),"",(F29-E29)*24) | H29: 4248 | I29: 4248 | J29: 3810 | K29: 0 | L29: 378 | M29: 36 | N29: 24 | O29: 34269 | P29: 12 | Q29: Scheduled run 39 đã đạt terminal state
A30: 46278 | B30: 00:30 | C30: Hoàn thành có lỗi | D30: 40 | E30: 46278.029 | F30: 46278.681 | G30: =IF(OR(E30="",F30=""),"",(F30-E30)*24) | H30: 4248 | I30: 4248 | J30: 3844 | K30: 0 | L30: 344 | M30: 36 | N30: 24 | O30: 34617 | P30: 12 | Q30: Scheduled run 40 đã đạt terminal state; save_artifacts=false; scraper_version=2.3.0
A31: 46279 | B31: 00:30 | C31: Hoàn thành có lỗi | D31: 41 | E31: 46279.019 | F31: 46279.672 | G31: =IF(OR(E31="",F31=""),"",(F31-E31)*24) | H31: 4248 | I31: 4248 | J31: 3834 | K31: 0 | L31: 354 | M31: 36 | N31: 24 | O31: 33868 | P31: 12 | Q31: Scheduled run 41 đã đạt terminal state
A32: 46280 | B32: 00:30 | C32: Hoàn thành có lỗi | D32: 42 | E32: 46280.023 | F32: 46280.677 | G32: =IF(OR(E32="",F32=""),"",(F32-E32)*24) | H32: 4248 | I32: 4248 | J32: 3819 | K32: 0 | L32: 357 | M32: 48 | N32: 24 | O32: 34515 | P32: 12 | Q32: Scheduled run 42 đã đạt terminal state
A33: 46281 | B33: 00:30 | C33: Hoàn thành có lỗi | D33: 43 | E33: 46281.024 | F33: 46281.688 | G33: =IF(OR(E33="",F33=""),"",(F33-E33)*24) | H33: 4248 | I33: 4248 | J33: 3834 | K33: 0 | L33: 354 | M33: 36 | N33: 24 | O33: 34954 | P33: 12 | Q33: Scheduled run 43 đã đạt terminal state
A34: 46282 | B34: 00:30 | C34: Hoàn thành có lỗi | D34: 44 | E34: 46282.024 | F34: 46282.656 | G34: =IF(OR(E34="",F34=""),"",(F34-E34)*24) | H34: 4248 | I34: 4248 | J34: 3755 | K34: 0 | L34: 361 | M34: 108 | N34: 24 | O34: 32953 | P34: 12 | Q34: Scheduled run 44 đã đạt terminal state
A35: 46283 | B35: 00:30 | C35: Hoàn thành có lỗi | D35: 45 | E35: 46283.024 | F35: 46283.664 | G35: =IF(OR(E35="",F35=""),"",(F35-E35)*24) | H35: 4248 | I35: 4248 | J35: 3764 | K35: 0 | L35: 364 | M35: 96 | N35: 24 | O35: 34805 | P35: 12 | Q35: Scheduled run 45 đã đạt terminal state
A36: 46284 | B36: 00:30 | C36: Hoàn thành có lỗi | D36: 46 | E36: 46284.023 | F36: 46284.663 | G36: =IF(OR(E36="",F36=""),"",(F36-E36)*24) | H36: 4248 | I36: 4248 | J36: 3767 | K36: 0 | L36: 397 | M36: 60 | N36: 24 | O36: 34329 | P36: 12 | Q36: Scheduled run 46 đã đạt terminal state
A37: 46285 | B37: 00:30 | C37: Hoàn thành có lỗi | D37: 47 | E37: 46285.091 | F37: 46285.744 | G37: =IF(OR(E37="",F37=""),"",(F37-E37)*24) | H37: 4248 | I37: 4248 | J37: 3817 | K37: 0 | L37: 359 | M37: 48 | N37: 24 | O37: 34172 | P37: 12 | Q37: Scheduled run 47 đã đạt terminal state
A38: 46286 | B38: 00:30 | C38: Hoàn thành có lỗi | D38: 48 | E38: 46286.023 | F38: 46286.664 | G38: =IF(OR(E38="",F38=""),"",(F38-E38)*24) | H38: 4248 | I38: 4248 | J38: 3813 | K38: 0 | L38: 363 | M38: 48 | N38: 24 | O38: 33015 | P38: 12 | Q38: Scheduled run 48 đã đạt terminal state
... A59: 46307 | B59: 00:30 | C59: Hoàn thành có lỗi | D59: 69 | E59: 46307.024 | F59: 46307.643 | G59: =IF(OR(E59="",F59=""),"",(F59-E59)*24) | H59: 4248 | I59: 4248 | J59: 3546 | K59: 0 | L59: 486 | M59: 84 | N59: 132 | O59: 32980 | P59: 12 | Q59: Scheduled run 69 đã đạt terminal state
A60: 46308 | B60: 00:30 | C60: Đang chạy | D60: 70 | E60: 46308.019 | G60: =IF(OR(E60="",F60=""),"",(F60-E60)*24) | P60: 12 | Q60: Scheduled crawl đã tạo durable run; save_artifacts=false
A61: 46309 | B61: 00:30 | C61: Chưa chạy | G61: =IF(OR(E61="",F61=""),"",(F61-E61)*24) | P61: 12
A62: 46310 | B62: 00:30 | C62: Chưa chạy | G62: =IF(OR(E62="",F62=""),"",(F62-E62)*24) | P62: 12
A63: 46311 | B63: 00:30 | C63: Chưa chạy | G63: =IF(OR(E63="",F63=""),"",(F63-E63)*24) | P63: 12
A64: 46312 | B64: 00:30 | C64: Chưa chạy | G64: =IF(OR(E64="",F64=""),"",(F64-E64)*24) | P64: 12
A65: 46313 | B65: 00:30 | C65: Chưa chạy | G65: =IF(OR(E65="",F65=""),"",(F65-E65)*24) | P65: 12
A66: 46314 | B66: 00:30 | C66: Chưa chạy | G66: =IF(OR(E66="",F66=""),"",(F66-E66)*24) | P66: 12
A67: 46315 | B67: 00:30 | C67: Chưa chạy | G67: =IF(OR(E67="",F67=""),"",(F67-E67)*24) | P67: 12
A68: 46316 | B68: 00:30 | C68: Chưa chạy | G68: =IF(OR(E68="",F68=""),"",(F68-E68)*24) | P68: 12
A69: 46317 | B69: 00:30 | C69: Chưa chạy | G69: =IF(OR(E69="",F69=""),"",(F69-E69)*24) | P69: 12
...

Sheet SLOT_RULES
A1: QUY TẮC CỐ ĐỊNH CHO 12 SLOT CHECK-IN
A3: Slot | B3: Nhóm | C3: Mốc đầu tiên | D3: Chu kỳ thay | E3: Vai trò | F3: Điều kiện đổi | G3: Checkout | H3: Ghi chú
A4: N1 | B4: Gần | C4: 46254 | D4: 28 ngày | E4: Rất gần — ngày thường | F4: Khi check-in < crawl date | G4: Check-in + 1 ngày | H4: Giữ cả ngày nhận phòng (lead time 0), roll từ hôm sau
A5: N2 | B5: Gần | C5: 46256 | D5: 28 ngày | E5: Rất gần — cuối tuần | F5: Khi check-in < crawl date | G5: Check-in + 1 ngày | H5: Giữ cả ngày nhận phòng (lead time 0), roll từ hôm sau
A6: N3 | B6: Gần | C6: 46259 | D6: 28 ngày | E6: Gần — ngày thường | F6: Khi check-in < crawl date | G6: Check-in + 1 ngày | H6: Giữ cả ngày nhận phòng (lead time 0), roll từ hôm sau
A7: N4 | B7: Gần | C7: 46263 | D7: 28 ngày | E7: Gần — cuối tuần | F7: Khi check-in < crawl date | G7: Check-in + 1 ngày | H7: Giữ cả ngày nhận phòng (lead time 0), roll từ hôm sau
A8: N5 | B8: Gần | C8: 46267 | D8: 28 ngày | E8: Gần — lễ/đối chứng | F8: Khi check-in < crawl date | G8: Check-in + 1 ngày | H8: Giữ cả ngày nhận phòng (lead time 0), roll từ hôm sau
A9: N6 | B9: Gần | C9: 46271 | D9: 28 ngày | E9: Gần — cuối tuần | F9: Khi check-in < crawl date | G9: Check-in + 1 ngày | H9: Giữ cả ngày nhận phòng (lead time 0), roll từ hôm sau
A10: N7 | B10: Gần | C10: 46274 | D10: 28 ngày | E10: Gần — ngày thường | F10: Khi check-in < crawl date | G10: Check-in + 1 ngày | H10: Giữ cả ngày nhận phòng (lead time 0), roll từ hôm sau
A11: N8 | B11: Gần | C11: 46277 | D11: 28 ngày | E11: Gần — cuối tuần | F11: Khi check-in < crawl date | G11: Check-in + 1 ngày | H11: Giữ cả ngày nhận phòng (lead time 0), roll từ hôm sau
A12: N9 | B12: Gần | C12: 46279 | D12: 28 ngày | E12: Gần — ngày thường | F12: Khi check-in < crawl date | G12: Check-in + 1 ngày | H12: Giữ cả ngày nhận phòng (lead time 0), roll từ hôm sau
A13: F1 | B13: Xa | C13: 46306 | D13: 56 ngày | E13: Xa gần — cuối tuần | F13: Khi check-in < crawl date | G13: Check-in + 1 ngày | H13: Giữ cả ngày nhận phòng; anchor xa tạo chuỗi quan sát dài
A14: F2 | B14: Xa | C14: 46344 | D14: 84 ngày | E14: Xa trung bình — ngày thường | F14: Khi check-in < crawl date | G14: Check-in + 1 ngày | H14: Giữ cả ngày nhận phòng; anchor xa tạo chuỗi quan sát dài
A15: F3 | B15: Xa | C15: 46388 | D15: 168 ngày | E15: Xa dài — ngày lễ | F15: Khi check-in < crawl date | G15: Check-in + 1 ngày | H15: Giữ cả ngày nhận phòng; anchor xa tạo chuỗi quan sát dài

Sheet AUTOMATION_CONFIG
A1: CẤU HÌNH AUTOMATION CỐ ĐỊNH
A3: Setting | B3: Value
A4: Schedule | B4: Mỗi ngày lúc 00:30
A5: Timezone | B5: Asia/Ho_Chi_Minh
A6: Active from | B6: 46252
A7: Active through | B7: 46356
A8: Project root | B8: D:/MSE/CAPSTONE/hotel-price-intelligence
A9: Hotel source | B9: D:/MSE/CAPSTONE/link_hotel_data_expanded.xlsx
A10: Calendar workbook | B10: D:/MSE/CAPSTONE/outputs/crawl-data-planner-20260816/crawl_sampling_master.xlsx
A11: Runner | B11: backend/scripts/run_scheduled_calendar.py
A12: Plan sheet | B12: DAILY_CRAWL_PLAN
A13: Log sheet | B13: CRAWL_LOG
A14: Save screenshots/HTML | B14: FALSE
A15: Runbook của recurring automation
A16: Mỗi ngày lúc 00:30 theo múi giờ Asia/Ho_Chi_Minh, thực hiện đúng một daily crawl cho project CAPSTONE. 1. Lấy ngày hiện tại theo Asia/Ho_Chi_Minh. Nếu ngoài 18/08/2026–30/11/2026 thì không tạo crawl; sau 30/11/2026 dừng automation. 2. Kiểm tra crawl_sampling_master.xlsx và link_hotel_data_expanded.xlsx đều tồn tại; không sao chép danh sách khách sạn vào workbook lịch. 3. Đọc đúng dòng hôm nay trong CRAWL_LOG. Nếu Status là Hoàn thành, Hoàn thành có lỗi hoặc Đang chạy thì thoát để tránh tạo job trùng. 4. Dùng Python backend chạy backend/scripts/run_scheduled_calendar.py với calendar và hotel-file ở trên. Khởi chạy bằng Windows PowerShell Hidden. 5. Runner đọc chính xác N1–N9 và F1–F3, xác minh 12 ngày khác nhau và không ngày nào ở quá khứ; lead time 0 hợp lệ. Không tự chọn hoặc đổi lịch. 6. Runner tự kiểm tra MySQL, khởi động worker nếu thiếu, tạo durable run với trigger_type=scheduled và save_artifacts=false, rồi cập nhật đúng một dòng CRAWL_LOG. 7. Background process theo dõi worker tới terminal state; automation Codex chỉ cần xác nhận process đã khởi động, không giữ turn mở nhiều giờ. 8. Không chụp ảnh, không lưu HTML.gz, không sửa lịch ngày khác và không xóa dữ liệu.

Sheet README
A1: CÁCH WORKBOOK VẬN HÀNH
A3: Bước | B3: Thời điểm | C3: Automation làm gì | D3: Đọc từ | E3: Ghi vào | F3: Lưu ý
A4: 1 | B4: 00:30 mỗi ngày | C4: Xác định ngày Asia/Ho_Chi_Minh | D4: Ngày hệ thống | E4: — | F4: Chạy từ 18/08 đến hết 30/11/2026
A5: 2 | B5: Ngay sau đó | C5: Tìm đúng một dòng lịch hôm nay | D5: DAILY_CRAWL_PLAN | E5: — | F5: Đọc 9 ngày gần và 3 ngày xa
A6: 3 | B6: Trước khi tạo job | C6: Kiểm tra status chống tạo trùng | D6: CRAWL_LOG | E6: CRAWL_LOG | F6: Ngày đã hoàn thành/đang chạy thì thoát
A7: 4 | B7: Khi tạo job | C7: Khởi chạy background calendar runner | D7: link_hotel_data_expanded.xlsx | E7: MySQL + Run IDs | F7: trigger_type=scheduled; save_artifacts=false
A8: 5 | B8: Trong khi chạy | C8: Theo dõi toàn bộ daily crawl | D8: Backend/MySQL | E8: Cùng một dòng CRAWL_LOG | F8: Không thêm dòng theo run
A9: 6 | B9: Khi kết thúc | C9: Ghi tổng kết và đánh dấu hoàn thành | D9: Run terminal counts | E9: Cùng dòng ngày crawl | F9: Có lỗi thì Hoàn thành có lỗi
A11: Quan trọng: nên đóng workbook Excel trước 00:30 để automation có thể ghi trạng thái sau khi crawl.
