Workbook

Sheet SUMMARY
A1: LỊCH CRAWL MÁY PHỤ — 02/09: 12 CHECK-IN; TỪ 03/09: 10 CHECK-IN
A3: Thông số | B3: Giá trị | D3: Kiểm tra | E3: Kết quả
A4: Ngày bắt đầu | B4: 46267 | D4: Số ngày mong đợi | E4: =B5-B4+1
A5: Ngày kết thúc | B5: 46356 | D5: Số dòng lịch thực tế | E5: =ROWS('AUX_CRAWL_PLAN'!A4:A93)
A6: Giờ bắt đầu mỗi ngày | B6: 00:30 | D6: 02/09 đủ 12; từ 03/09 đủ 10 | E6: =IF(COUNTIF('AUX_CRAWL_PLAN'!S4:S93,"FAIL")=0,"PASS","FAIL")
A7: Múi giờ | B7: Asia/Ho_Chi_Minh | D7: Không trùng local chính | E7: =IF(COUNTIF('AUX_CRAWL_PLAN'!T4:T93,"FAIL")=0,"PASS","FAIL")
A8: Tổng số ngày theo lịch | B8: ='AUX_CRAWL_PLAN'!A93-'AUX_CRAWL_PLAN'!A4+1 | D8: Không trùng VPS | E8: =IF(COUNTIF('AUX_CRAWL_PLAN'!U4:U93,"FAIL")=0,"PASS","FAIL")
A9: Số khách sạn (cohort v2) | B9: 354 | D9: Không trùng nội bộ máy phụ | E9: =IF(COUNTIF('AUX_CRAWL_PLAN'!V4:V93,"FAIL")=0,"PASS","FAIL")
A10: Check-in mỗi ngày từ 03/09 | B10: 10 | D10: Benchmark capacity máy phụ | E10: ="PENDING"
A11: Item dự kiến mỗi ngày từ 03/09 | B11: =B9*B10 | D11: Dead-link two-confirmation đã deploy | E11: ="PENDING"
A12: Tổng item lý thuyết | B12: =B9*12+B9*B10*(B8-1) | D12: Trạng thái kỹ thuật workbook | E12: =IF(AND(E4=E5,E6="PASS",E7="PASS",E8="PASS",E9="PASS"),"PASS — chờ 2 gate vận hành","FAIL")
A13: Đã hoàn thành | B13: =COUNTIFS('CRAWL_LOG'!B4:B93,"Hoàn thành")+COUNTIFS('CRAWL_LOG'!B4:B93,"Hoàn thành có lỗi")
A14: Chưa chạy | B14: =COUNTIF('CRAWL_LOG'!B4:B93,"Chưa chạy")
A16: Máy phụ là nguồn thứ ba độc lập (local_aux). Lượt 02/09 giữ 12 check-in; từ 03/09 dùng 7 near + 3 far để giảm tải. Cohort v2 có 354 khách sạn. Không thay đổi lịch local chính hoặc VPS.

Sheet AUX_CRAWL_PLAN
A1: AUX-LOCAL CRAWL PLAN — 02/09: 12 SLOT; TỪ 03/09: 10 SLOT (7 NEAR + 3 FAR)
A2: Từ 03/09, AN2 và AN3 ngừng sử dụng; giữ AN1, AN4–AN9 và AF1–AF3. Mọi ngày vẫn đối chiếu local chính/VPS; roll khi check-in < crawl date; lead time 0 hợp lệ.
A3: Crawl date | B3: Thứ | C3: Phase | D3: Start time (ICT) | E3: AN1 | F3: AN2 (chỉ 02/09) | G3: AN3 (chỉ 02/09) | H3: AN4 | I3: AN5 | J3: AN6 | K3: AN7 | L3: AN8 | M3: AN9 | N3: AF1 | O3: AF2 | P3: AF3 | Q3: Min lead | R3: Max lead | S3: Số ngày hợp lệ | T3: Không trùng local | U3: Không trùng VPS | V3: Không trùng nội bộ | W3: Crawl status | X3: Sampling note
A4: 46267 | B4: Thứ Tư | C4: Official | D4: 00:30 | E4: ='SLOT_RULES'!$D$4+IF($A4<='SLOT_RULES'!$D$4,0,INT(($A4-'SLOT_RULES'!$D$4-1)/'SLOT_RULES'!$E$4)+1)*'SLOT_RULES'!$E$4 | F4: ='SLOT_RULES'!$D$5+IF($A4<='SLOT_RULES'!$D$5,0,INT(($A4-'SLOT_RULES'!$D$5-1)/'SLOT_RULES'!$E$5)+1)*'SLOT_RULES'!$E$5 | G4: ='SLOT_RULES'!$D$6+IF($A4<='SLOT_RULES'!$D$6,0,INT(($A4-'SLOT_RULES'!$D$6-1)/'SLOT_RULES'!$E$6)+1)*'SLOT_RULES'!$E$6 | H4: ='SLOT_RULES'!$D$7+IF($A4<='SLOT_RULES'!$D$7,0,INT(($A4-'SLOT_RULES'!$D$7-1)/'SLOT_RULES'!$E$7)+1)*'SLOT_RULES'!$E$7 | I4: ='SLOT_RULES'!$D$8+IF($A4<='SLOT_RULES'!$D$8,0,INT(($A4-'SLOT_RULES'!$D$8-1)/'SLOT_RULES'!$E$8)+1)*'SLOT_RULES'!$E$8 | J4: ='SLOT_RULES'!$D$9+IF($A4<='SLOT_RULES'!$D$9,0,INT(($A4-'SLOT_RULES'!$D$9-1)/'SLOT_RULES'!$E$9)+1)*'SLOT_RULES'!$E$9 | K4: ='SLOT_RULES'!$D$10+IF($A4<='SLOT_RULES'!$D$10,0,INT(($A4-'SLOT_RULES'!$D$10-1)/'SLOT_RULES'!$E$10)+1)*'SLOT_RULES'!$E$10 | L4: ='SLOT_RULES'!$D$11+IF($A4<='SLOT_RULES'!$D$11,0,INT(($A4-'SLOT_RULES'!$D$11-1)/'SLOT_RULES'!$E$11)+1)*'SLOT_RULES'!$E$11 | M4: ='SLOT_RULES'!$D$12+IF($A4<='SLOT_RULES'!$D$12,0,INT(($A4-'SLOT_RULES'!$D$12-1)/'SLOT_RULES'!$E$12)+1)*'SLOT_RULES'!$E$12 | N4: ='SLOT_RULES'!$D$13+IF($A4<='SLOT_RULES'!$D$13,0,INT(($A4-'SLOT_RULES'!$D$13-1)/'SLOT_RULES'!$E$13)+1)*'SLOT_RULES'!$E$13 | O4: ='SLOT_RULES'!$D$14+IF($A4<='SLOT_RULES'!$D$14,0,INT(($A4-'SLOT_RULES'!$D$14-1)/'SLOT_RULES'!$E$14)+1)*'SLOT_RULES'!$E$14 | P4: ='SLOT_RULES'!$D$15+IF($A4<='SLOT_RULES'!$D$15,0,INT(($A4-'SLOT_RULES'!$D$15-1)/'SLOT_RULES'!$E$15)+1)*'SLOT_RULES'!$E$15 | Q4: =MIN(E4:P4)-A4 | R4: =MAX(E4:P4)-A4 | S4: =IF(AND(COUNT(E4:P4)=12,MIN(E4:P4)>=A4),"PASS","FAIL") | T4: =IF((COUNTIF('LOCAL_REFERENCE'!$D4:$O4,E4)+COUNTIF('LOCAL_REFERENCE'!$D4:$O4,F4)+COUNTIF('LOCAL_REFERENCE'!$D4:$O4,G4)+COUNTIF('LOCAL_REFERENCE'!$D4:$O4,H4)+COUNTIF('LOCAL_REFERENCE'!$D4:$O4,I4)+COUNTIF('LOCAL_REFERENCE'!$D4:$O4,J4)+COUNTIF('LOCAL_REFERENCE'!$D4:$O4,K4)+COUNTIF('LOCAL_REFERENCE'!$D4:$O4,L4)+COUNTIF('LOCAL_REFERENCE'!$D4:$O4,M4)+COUNTIF('LOCAL_REFERENCE'!$D4:$O4,N4)+COUNTIF('LOCAL_REFERENCE'!$D4:$O4,O4)+COUNTIF('LOCAL_REFERENCE'!$D4:$O4,P4))=0,"PASS","FAIL") | U4: =IF((COUNTIF('VPS_REFERENCE'!$D4:$H4,E4)+COUNTIF('VPS_REFERENCE'!$D4:$H4,F4)+COUNTIF('VPS_REFERENCE'!$D4:$H4,G4)+COUNTIF('VPS_REFERENCE'!$D4:$H4,H4)+COUNTIF('VPS_REFERENCE'!$D4:$H4,I4)+COUNTIF('VPS_REFERENCE'!$D4:$H4,J4)+COUNTIF('VPS_REFERENCE'!$D4:$H4,K4)+COUNTIF('VPS_REFERENCE'!$D4:$H4,L4)+COUNTIF('VPS_REFERENCE'!$D4:$H4,M4)+COUNTIF('VPS_REFERENCE'!$D4:$H4,N4)+COUNTIF('VPS_REFERENCE'!$D4:$H4,O4)+COUNTIF('VPS_REFERENCE'!$D4:$H4,P4))=0,"PASS","FAIL") | V4: =IF(OR(E4=F4,E4=G4,E4=H4,E4=I4,E4=J4,E4=K4,E4=L4,E4=M4,E4=N4,E4=O4,E4=P4,F4=G4,F4=H4,F4=I4,F4=J4,F4=K4,F4=L4,F4=M4,F4=N4,F4=O4,F4=P4,G4=H4,G4=I4,G4=J4,G4=K4,G4=L4,G4=M4,G4=N4,G4=O4,G4=P4,H4=I4,H4=J4,H4=K4,H4=L4,H4=M4,H4=N4,H4=O4,H4=P4,I4=J4,I4=K4,I4=L4,I4=M4,I4=N4,I4=O4,I4=P4,J4=K4,J4=L4,J4=M4,J4=N4,J4=O4,J4=P4,K4=L4,K4=M4,K4=N4,K4=O4,K4=P4,L4=M4,L4=N4,L4=O4,L4=P4,M4=N4,M4=O4,M4=P4,N4=O4,N4=P4,O4=P4),"FAIL","PASS") | W4: ='CRAWL_LOG'!B4 | X4: Lượt đầu 02/09 giữ 12 slot; chuyển sang 10 slot từ ngày kế tiếp
A5: 46268 | B5: Thứ Năm | C5: Official | D5: 00:30 | E5: ='SLOT_RULES'!$D$4+IF($A5<='SLOT_RULES'!$D$4,0,INT(($A5-'SLOT_RULES'!$D$4-1)/'SLOT_RULES'!$E$4)+1)*'SLOT_RULES'!$E$4 | H5: ='SLOT_RULES'!$D$7+IF($A5<='SLOT_RULES'!$D$7,0,INT(($A5-'SLOT_RULES'!$D$7-1)/'SLOT_RULES'!$E$7)+1)*'SLOT_RULES'!$E$7 | I5: ='SLOT_RULES'!$D$8+IF($A5<='SLOT_RULES'!$D$8,0,INT(($A5-'SLOT_RULES'!$D$8-1)/'SLOT_RULES'!$E$8)+1)*'SLOT_RULES'!$E$8 | J5: ='SLOT_RULES'!$D$9+IF($A5<='SLOT_RULES'!$D$9,0,INT(($A5-'SLOT_RULES'!$D$9-1)/'SLOT_RULES'!$E$9)+1)*'SLOT_RULES'!$E$9 | K5: ='SLOT_RULES'!$D$10+IF($A5<='SLOT_RULES'!$D$10,0,INT(($A5-'SLOT_RULES'!$D$10-1)/'SLOT_RULES'!$E$10)+1)*'SLOT_RULES'!$E$10 | L5: ='SLOT_RULES'!$D$11+IF($A5<='SLOT_RULES'!$D$11,0,INT(($A5-'SLOT_RULES'!$D$11-1)/'SLOT_RULES'!$E$11)+1)*'SLOT_RULES'!$E$11 | M5: ='SLOT_RULES'!$D$12+IF($A5<='SLOT_RULES'!$D$12,0,INT(($A5-'SLOT_RULES'!$D$12-1)/'SLOT_RULES'!$E$12)+1)*'SLOT_RULES'!$E$12 | N5: ='SLOT_RULES'!$D$13+IF($A5<='SLOT_RULES'!$D$13,0,INT(($A5-'SLOT_RULES'!$D$13-1)/'SLOT_RULES'!$E$13)+1)*'SLOT_RULES'!$E$13 | O5: ='SLOT_RULES'!$D$14+IF($A5<='SLOT_RULES'!$D$14,0,INT(($A5-'SLOT_RULES'!$D$14-1)/'SLOT_RULES'!$E$14)+1)*'SLOT_RULES'!$E$14 | P5: ='SLOT_RULES'!$D$15+IF($A5<='SLOT_RULES'!$D$15,0,INT(($A5-'SLOT_RULES'!$D$15-1)/'SLOT_RULES'!$E$15)+1)*'SLOT_RULES'!$E$15 | Q5: =MIN(E5:P5)-A5 | R5: =MAX(E5:P5)-A5 | S5: =IF(AND(COUNT(E5:P5)=10,MIN(E5:P5)>=A5),"PASS","FAIL") | T5: =IF((COUNTIF('LOCAL_REFERENCE'!$D5:$O5,E5)+COUNTIF('LOCAL_REFERENCE'!$D5:$O5,H5)+COUNTIF('LOCAL_REFERENCE'!$D5:$O5,I5)+COUNTIF('LOCAL_REFERENCE'!$D5:$O5,J5)+COUNTIF('LOCAL_REFERENCE'!$D5:$O5,K5)+COUNTIF('LOCAL_REFERENCE'!$D5:$O5,L5)+COUNTIF('LOCAL_REFERENCE'!$D5:$O5,M5)+COUNTIF('LOCAL_REFERENCE'!$D5:$O5,N5)+COUNTIF('LOCAL_REFERENCE'!$D5:$O5,O5)+COUNTIF('LOCAL_REFERENCE'!$D5:$O5,P5))=0,"PASS","FAIL") | U5: =IF((COUNTIF('VPS_REFERENCE'!$D5:$H5,E5)+COUNTIF('VPS_REFERENCE'!$D5:$H5,H5)+COUNTIF('VPS_REFERENCE'!$D5:$H5,I5)+COUNTIF('VPS_REFERENCE'!$D5:$H5,J5)+COUNTIF('VPS_REFERENCE'!$D5:$H5,K5)+COUNTIF('VPS_REFERENCE'!$D5:$H5,L5)+COUNTIF('VPS_REFERENCE'!$D5:$H5,M5)+COUNTIF('VPS_REFERENCE'!$D5:$H5,N5)+COUNTIF('VPS_REFERENCE'!$D5:$H5,O5)+COUNTIF('VPS_REFERENCE'!$D5:$H5,P5))=0,"PASS","FAIL") | V5: =IF(OR(E5=H5,E5=I5,E5=J5,E5=K5,E5=L5,E5=M5,E5=N5,E5=O5,E5=P5,H5=I5,H5=J5,H5=K5,H5=L5,H5=M5,H5=N5,H5=O5,H5=P5,I5=J5,I5=K5,I5=L5,I5=M5,I5=N5,I5=O5,I5=P5,J5=K5,J5=L5,J5=M5,J5=N5,J5=O5,J5=P5,K5=L5,K5=M5,K5=N5,K5=O5,K5=P5,L5=M5,L5=N5,L5=O5,L5=P5,M5=N5,M5=O5,M5=P5,N5=O5,N5=P5,O5=P5),"FAIL","PASS") | W5: ='CRAWL_LOG'!B5 | X5: 10-slot panel: 7 near + 3 far; AN2/AN3 inactive from 03/09
A6: 46269 | B6: Thứ Sáu | C6: Official | D6: 00:30 | E6: ='SLOT_RULES'!$D$4+IF($A6<='SLOT_RULES'!$D$4,0,INT(($A6-'SLOT_RULES'!$D$4-1)/'SLOT_RULES'!$E$4)+1)*'SLOT_RULES'!$E$4 | H6: ='SLOT_RULES'!$D$7+IF($A6<='SLOT_RULES'!$D$7,0,INT(($A6-'SLOT_RULES'!$D$7-1)/'SLOT_RULES'!$E$7)+1)*'SLOT_RULES'!$E$7 | I6: ='SLOT_RULES'!$D$8+IF($A6<='SLOT_RULES'!$D$8,0,INT(($A6-'SLOT_RULES'!$D$8-1)/'SLOT_RULES'!$E$8)+1)*'SLOT_RULES'!$E$8 | J6: ='SLOT_RULES'!$D$9+IF($A6<='SLOT_RULES'!$D$9,0,INT(($A6-'SLOT_RULES'!$D$9-1)/'SLOT_RULES'!$E$9)+1)*'SLOT_RULES'!$E$9 | K6: ='SLOT_RULES'!$D$10+IF($A6<='SLOT_RULES'!$D$10,0,INT(($A6-'SLOT_RULES'!$D$10-1)/'SLOT_RULES'!$E$10)+1)*'SLOT_RULES'!$E$10 | L6: ='SLOT_RULES'!$D$11+IF($A6<='SLOT_RULES'!$D$11,0,INT(($A6-'SLOT_RULES'!$D$11-1)/'SLOT_RULES'!$E$11)+1)*'SLOT_RULES'!$E$11 | M6: ='SLOT_RULES'!$D$12+IF($A6<='SLOT_RULES'!$D$12,0,INT(($A6-'SLOT_RULES'!$D$12-1)/'SLOT_RULES'!$E$12)+1)*'SLOT_RULES'!$E$12 | N6: ='SLOT_RULES'!$D$13+IF($A6<='SLOT_RULES'!$D$13,0,INT(($A6-'SLOT_RULES'!$D$13-1)/'SLOT_RULES'!$E$13)+1)*'SLOT_RULES'!$E$13 | O6: ='SLOT_RULES'!$D$14+IF($A6<='SLOT_RULES'!$D$14,0,INT(($A6-'SLOT_RULES'!$D$14-1)/'SLOT_RULES'!$E$14)+1)*'SLOT_RULES'!$E$14 | P6: ='SLOT_RULES'!$D$15+IF($A6<='SLOT_RULES'!$D$15,0,INT(($A6-'SLOT_RULES'!$D$15-1)/'SLOT_RULES'!$E$15)+1)*'SLOT_RULES'!$E$15 | Q6: =MIN(E6:P6)-A6 | R6: =MAX(E6:P6)-A6 | S6: =IF(AND(COUNT(E6:P6)=10,MIN(E6:P6)>=A6),"PASS","FAIL") | T6: =IF((COUNTIF('LOCAL_REFERENCE'!$D6:$O6,E6)+COUNTIF('LOCAL_REFERENCE'!$D6:$O6,H6)+COUNTIF('LOCAL_REFERENCE'!$D6:$O6,I6)+COUNTIF('LOCAL_REFERENCE'!$D6:$O6,J6)+COUNTIF('LOCAL_REFERENCE'!$D6:$O6,K6)+COUNTIF('LOCAL_REFERENCE'!$D6:$O6,L6)+COUNTIF('LOCAL_REFERENCE'!$D6:$O6,M6)+COUNTIF('LOCAL_REFERENCE'!$D6:$O6,N6)+COUNTIF('LOCAL_REFERENCE'!$D6:$O6,O6)+COUNTIF('LOCAL_REFERENCE'!$D6:$O6,P6))=0,"PASS","FAIL") | U6: =IF((COUNTIF('VPS_REFERENCE'!$D6:$H6,E6)+COUNTIF('VPS_REFERENCE'!$D6:$H6,H6)+COUNTIF('VPS_REFERENCE'!$D6:$H6,I6)+COUNTIF('VPS_REFERENCE'!$D6:$H6,J6)+COUNTIF('VPS_REFERENCE'!$D6:$H6,K6)+COUNTIF('VPS_REFERENCE'!$D6:$H6,L6)+COUNTIF('VPS_REFERENCE'!$D6:$H6,M6)+COUNTIF('VPS_REFERENCE'!$D6:$H6,N6)+COUNTIF('VPS_REFERENCE'!$D6:$H6,O6)+COUNTIF('VPS_REFERENCE'!$D6:$H6,P6))=0,"PASS","FAIL") | V6: =IF(OR(E6=H6,E6=I6,E6=J6,E6=K6,E6=L6,E6=M6,E6=N6,E6=O6,E6=P6,H6=I6,H6=J6,H6=K6,H6=L6,H6=M6,H6=N6,H6=O6,H6=P6,I6=J6,I6=K6,I6=L6,I6=M6,I6=N6,I6=O6,I6=P6,J6=K6,J6=L6,J6=M6,J6=N6,J6=O6,J6=P6,K6=L6,K6=M6,K6=N6,K6=O6,K6=P6,L6=M6,L6=N6,L6=O6,L6=P6,M6=N6,M6=O6,M6=P6,N6=O6,N6=P6,O6=P6),"FAIL","PASS") | W6: ='CRAWL_LOG'!B6 | X6: 10-slot panel: 7 near + 3 far; AN2/AN3 inactive from 03/09
A7: 46270 | B7: Thứ Bảy | C7: Official | D7: 00:30 | E7: ='SLOT_RULES'!$D$4+IF($A7<='SLOT_RULES'!$D$4,0,INT(($A7-'SLOT_RULES'!$D$4-1)/'SLOT_RULES'!$E$4)+1)*'SLOT_RULES'!$E$4 | H7: ='SLOT_RULES'!$D$7+IF($A7<='SLOT_RULES'!$D$7,0,INT(($A7-'SLOT_RULES'!$D$7-1)/'SLOT_RULES'!$E$7)+1)*'SLOT_RULES'!$E$7 | I7: ='SLOT_RULES'!$D$8+IF($A7<='SLOT_RULES'!$D$8,0,INT(($A7-'SLOT_RULES'!$D$8-1)/'SLOT_RULES'!$E$8)+1)*'SLOT_RULES'!$E$8 | J7: ='SLOT_RULES'!$D$9+IF($A7<='SLOT_RULES'!$D$9,0,INT(($A7-'SLOT_RULES'!$D$9-1)/'SLOT_RULES'!$E$9)+1)*'SLOT_RULES'!$E$9 | K7: ='SLOT_RULES'!$D$10+IF($A7<='SLOT_RULES'!$D$10,0,INT(($A7-'SLOT_RULES'!$D$10-1)/'SLOT_RULES'!$E$10)+1)*'SLOT_RULES'!$E$10 | L7: ='SLOT_RULES'!$D$11+IF($A7<='SLOT_RULES'!$D$11,0,INT(($A7-'SLOT_RULES'!$D$11-1)/'SLOT_RULES'!$E$11)+1)*'SLOT_RULES'!$E$11 | M7: ='SLOT_RULES'!$D$12+IF($A7<='SLOT_RULES'!$D$12,0,INT(($A7-'SLOT_RULES'!$D$12-1)/'SLOT_RULES'!$E$12)+1)*'SLOT_RULES'!$E$12 | N7: ='SLOT_RULES'!$D$13+IF($A7<='SLOT_RULES'!$D$13,0,INT(($A7-'SLOT_RULES'!$D$13-1)/'SLOT_RULES'!$E$13)+1)*'SLOT_RULES'!$E$13 | O7: ='SLOT_RULES'!$D$14+IF($A7<='SLOT_RULES'!$D$14,0,INT(($A7-'SLOT_RULES'!$D$14-1)/'SLOT_RULES'!$E$14)+1)*'SLOT_RULES'!$E$14 | P7: ='SLOT_RULES'!$D$15+IF($A7<='SLOT_RULES'!$D$15,0,INT(($A7-'SLOT_RULES'!$D$15-1)/'SLOT_RULES'!$E$15)+1)*'SLOT_RULES'!$E$15 | Q7: =MIN(E7:P7)-A7 | R7: =MAX(E7:P7)-A7 | S7: =IF(AND(COUNT(E7:P7)=10,MIN(E7:P7)>=A7),"PASS","FAIL") | T7: =IF((COUNTIF('LOCAL_REFERENCE'!$D7:$O7,E7)+COUNTIF('LOCAL_REFERENCE'!$D7:$O7,H7)+COUNTIF('LOCAL_REFERENCE'!$D7:$O7,I7)+COUNTIF('LOCAL_REFERENCE'!$D7:$O7,J7)+COUNTIF('LOCAL_REFERENCE'!$D7:$O7,K7)+COUNTIF('LOCAL_REFERENCE'!$D7:$O7,L7)+COUNTIF('LOCAL_REFERENCE'!$D7:$O7,M7)+COUNTIF('LOCAL_REFERENCE'!$D7:$O7,N7)+COUNTIF('LOCAL_REFERENCE'!$D7:$O7,O7)+COUNTIF('LOCAL_REFERENCE'!$D7:$O7,P7))=0,"PASS","FAIL") | U7: =IF((COUNTIF('VPS_REFERENCE'!$D7:$H7,E7)+COUNTIF('VPS_REFERENCE'!$D7:$H7,H7)+COUNTIF('VPS_REFERENCE'!$D7:$H7,I7)+COUNTIF('VPS_REFERENCE'!$D7:$H7,J7)+COUNTIF('VPS_REFERENCE'!$D7:$H7,K7)+COUNTIF('VPS_REFERENCE'!$D7:$H7,L7)+COUNTIF('VPS_REFERENCE'!$D7:$H7,M7)+COUNTIF('VPS_REFERENCE'!$D7:$H7,N7)+COUNTIF('VPS_REFERENCE'!$D7:$H7,O7)+COUNTIF('VPS_REFERENCE'!$D7:$H7,P7))=0,"PASS","FAIL") | V7: =IF(OR(E7=H7,E7=I7,E7=J7,E7=K7,E7=L7,E7=M7,E7=N7,E7=O7,E7=P7,H7=I7,H7=J7,H7=K7,H7=L7,H7=M7,H7=N7,H7=O7,H7=P7,I7=J7,I7=K7,I7=L7,I7=M7,I7=N7,I7=O7,I7=P7,J7=K7,J7=L7,J7=M7,J7=N7,J7=O7,J7=P7,K7=L7,K7=M7,K7=N7,K7=O7,K7=P7,L7=M7,L7=N7,L7=O7,L7=P7,M7=N7,M7=O7,M7=P7,N7=O7,N7=P7,O7=P7),"FAIL","PASS") | W7: ='CRAWL_LOG'!B7 | X7: 10-slot panel: 7 near + 3 far; AN2/AN3 inactive from 03/09
A8: 46271 | B8: Chủ Nhật | C8: Official | D8: 00:30 | E8: ='SLOT_RULES'!$D$4+IF($A8<='SLOT_RULES'!$D$4,0,INT(($A8-'SLOT_RULES'!$D$4-1)/'SLOT_RULES'!$E$4)+1)*'SLOT_RULES'!$E$4 | H8: ='SLOT_RULES'!$D$7+IF($A8<='SLOT_RULES'!$D$7,0,INT(($A8-'SLOT_RULES'!$D$7-1)/'SLOT_RULES'!$E$7)+1)*'SLOT_RULES'!$E$7 | I8: ='SLOT_RULES'!$D$8+IF($A8<='SLOT_RULES'!$D$8,0,INT(($A8-'SLOT_RULES'!$D$8-1)/'SLOT_RULES'!$E$8)+1)*'SLOT_RULES'!$E$8 | J8: ='SLOT_RULES'!$D$9+IF($A8<='SLOT_RULES'!$D$9,0,INT(($A8-'SLOT_RULES'!$D$9-1)/'SLOT_RULES'!$E$9)+1)*'SLOT_RULES'!$E$9 | K8: ='SLOT_RULES'!$D$10+IF($A8<='SLOT_RULES'!$D$10,0,INT(($A8-'SLOT_RULES'!$D$10-1)/'SLOT_RULES'!$E$10)+1)*'SLOT_RULES'!$E$10 | L8: ='SLOT_RULES'!$D$11+IF($A8<='SLOT_RULES'!$D$11,0,INT(($A8-'SLOT_RULES'!$D$11-1)/'SLOT_RULES'!$E$11)+1)*'SLOT_RULES'!$E$11 | M8: ='SLOT_RULES'!$D$12+IF($A8<='SLOT_RULES'!$D$12,0,INT(($A8-'SLOT_RULES'!$D$12-1)/'SLOT_RULES'!$E$12)+1)*'SLOT_RULES'!$E$12 | N8: ='SLOT_RULES'!$D$13+IF($A8<='SLOT_RULES'!$D$13,0,INT(($A8-'SLOT_RULES'!$D$13-1)/'SLOT_RULES'!$E$13)+1)*'SLOT_RULES'!$E$13 | O8: ='SLOT_RULES'!$D$14+IF($A8<='SLOT_RULES'!$D$14,0,INT(($A8-'SLOT_RULES'!$D$14-1)/'SLOT_RULES'!$E$14)+1)*'SLOT_RULES'!$E$14 | P8: ='SLOT_RULES'!$D$15+IF($A8<='SLOT_RULES'!$D$15,0,INT(($A8-'SLOT_RULES'!$D$15-1)/'SLOT_RULES'!$E$15)+1)*'SLOT_RULES'!$E$15 | Q8: =MIN(E8:P8)-A8 | R8: =MAX(E8:P8)-A8 | S8: =IF(AND(COUNT(E8:P8)=10,MIN(E8:P8)>=A8),"PASS","FAIL") | T8: =IF((COUNTIF('LOCAL_REFERENCE'!$D8:$O8,E8)+COUNTIF('LOCAL_REFERENCE'!$D8:$O8,H8)+COUNTIF('LOCAL_REFERENCE'!$D8:$O8,I8)+COUNTIF('LOCAL_REFERENCE'!$D8:$O8,J8)+COUNTIF('LOCAL_REFERENCE'!$D8:$O8,K8)+COUNTIF('LOCAL_REFERENCE'!$D8:$O8,L8)+COUNTIF('LOCAL_REFERENCE'!$D8:$O8,M8)+COUNTIF('LOCAL_REFERENCE'!$D8:$O8,N8)+COUNTIF('LOCAL_REFERENCE'!$D8:$O8,O8)+COUNTIF('LOCAL_REFERENCE'!$D8:$O8,P8))=0,"PASS","FAIL") | U8: =IF((COUNTIF('VPS_REFERENCE'!$D8:$H8,E8)+COUNTIF('VPS_REFERENCE'!$D8:$H8,H8)+COUNTIF('VPS_REFERENCE'!$D8:$H8,I8)+COUNTIF('VPS_REFERENCE'!$D8:$H8,J8)+COUNTIF('VPS_REFERENCE'!$D8:$H8,K8)+COUNTIF('VPS_REFERENCE'!$D8:$H8,L8)+COUNTIF('VPS_REFERENCE'!$D8:$H8,M8)+COUNTIF('VPS_REFERENCE'!$D8:$H8,N8)+COUNTIF('VPS_REFERENCE'!$D8:$H8,O8)+COUNTIF('VPS_REFERENCE'!$D8:$H8,P8))=0,"PASS","FAIL") | V8: =IF(OR(E8=H8,E8=I8,E8=J8,E8=K8,E8=L8,E8=M8,E8=N8,E8=O8,E8=P8,H8=I8,H8=J8,H8=K8,H8=L8,H8=M8,H8=N8,H8=O8,H8=P8,I8=J8,I8=K8,I8=L8,I8=M8,I8=N8,I8=O8,I8=P8,J8=K8,J8=L8,J8=M8,J8=N8,J8=O8,J8=P8,K8=L8,K8=M8,K8=N8,K8=O8,K8=P8,L8=M8,L8=N8,L8=O8,L8=P8,M8=N8,M8=O8,M8=P8,N8=O8,N8=P8,O8=P8),"FAIL","PASS") | W8: ='CRAWL_LOG'!B8 | X8: 10-slot panel: 7 near + 3 far; AN2/AN3 inactive from 03/09
A9: 46272 | B9: Thứ Hai | C9: Official | D9: 00:30 | E9: ='SLOT_RULES'!$D$4+IF($A9<='SLOT_RULES'!$D$4,0,INT(($A9-'SLOT_RULES'!$D$4-1)/'SLOT_RULES'!$E$4)+1)*'SLOT_RULES'!$E$4 | H9: ='SLOT_RULES'!$D$7+IF($A9<='SLOT_RULES'!$D$7,0,INT(($A9-'SLOT_RULES'!$D$7-1)/'SLOT_RULES'!$E$7)+1)*'SLOT_RULES'!$E$7 | I9: ='SLOT_RULES'!$D$8+IF($A9<='SLOT_RULES'!$D$8,0,INT(($A9-'SLOT_RULES'!$D$8-1)/'SLOT_RULES'!$E$8)+1)*'SLOT_RULES'!$E$8 | J9: ='SLOT_RULES'!$D$9+IF($A9<='SLOT_RULES'!$D$9,0,INT(($A9-'SLOT_RULES'!$D$9-1)/'SLOT_RULES'!$E$9)+1)*'SLOT_RULES'!$E$9 | K9: ='SLOT_RULES'!$D$10+IF($A9<='SLOT_RULES'!$D$10,0,INT(($A9-'SLOT_RULES'!$D$10-1)/'SLOT_RULES'!$E$10)+1)*'SLOT_RULES'!$E$10 | L9: ='SLOT_RULES'!$D$11+IF($A9<='SLOT_RULES'!$D$11,0,INT(($A9-'SLOT_RULES'!$D$11-1)/'SLOT_RULES'!$E$11)+1)*'SLOT_RULES'!$E$11 | M9: ='SLOT_RULES'!$D$12+IF($A9<='SLOT_RULES'!$D$12,0,INT(($A9-'SLOT_RULES'!$D$12-1)/'SLOT_RULES'!$E$12)+1)*'SLOT_RULES'!$E$12 | N9: ='SLOT_RULES'!$D$13+IF($A9<='SLOT_RULES'!$D$13,0,INT(($A9-'SLOT_RULES'!$D$13-1)/'SLOT_RULES'!$E$13)+1)*'SLOT_RULES'!$E$13 | O9: ='SLOT_RULES'!$D$14+IF($A9<='SLOT_RULES'!$D$14,0,INT(($A9-'SLOT_RULES'!$D$14-1)/'SLOT_RULES'!$E$14)+1)*'SLOT_RULES'!$E$14 | P9: ='SLOT_RULES'!$D$15+IF($A9<='SLOT_RULES'!$D$15,0,INT(($A9-'SLOT_RULES'!$D$15-1)/'SLOT_RULES'!$E$15)+1)*'SLOT_RULES'!$E$15 | Q9: =MIN(E9:P9)-A9 | R9: =MAX(E9:P9)-A9 | S9: =IF(AND(COUNT(E9:P9)=10,MIN(E9:P9)>=A9),"PASS","FAIL") | T9: =IF((COUNTIF('LOCAL_REFERENCE'!$D9:$O9,E9)+COUNTIF('LOCAL_REFERENCE'!$D9:$O9,H9)+COUNTIF('LOCAL_REFERENCE'!$D9:$O9,I9)+COUNTIF('LOCAL_REFERENCE'!$D9:$O9,J9)+COUNTIF('LOCAL_REFERENCE'!$D9:$O9,K9)+COUNTIF('LOCAL_REFERENCE'!$D9:$O9,L9)+COUNTIF('LOCAL_REFERENCE'!$D9:$O9,M9)+COUNTIF('LOCAL_REFERENCE'!$D9:$O9,N9)+COUNTIF('LOCAL_REFERENCE'!$D9:$O9,O9)+COUNTIF('LOCAL_REFERENCE'!$D9:$O9,P9))=0,"PASS","FAIL") | U9: =IF((COUNTIF('VPS_REFERENCE'!$D9:$H9,E9)+COUNTIF('VPS_REFERENCE'!$D9:$H9,H9)+COUNTIF('VPS_REFERENCE'!$D9:$H9,I9)+COUNTIF('VPS_REFERENCE'!$D9:$H9,J9)+COUNTIF('VPS_REFERENCE'!$D9:$H9,K9)+COUNTIF('VPS_REFERENCE'!$D9:$H9,L9)+COUNTIF('VPS_REFERENCE'!$D9:$H9,M9)+COUNTIF('VPS_REFERENCE'!$D9:$H9,N9)+COUNTIF('VPS_REFERENCE'!$D9:$H9,O9)+COUNTIF('VPS_REFERENCE'!$D9:$H9,P9))=0,"PASS","FAIL") | V9: =IF(OR(E9=H9,E9=I9,E9=J9,E9=K9,E9=L9,E9=M9,E9=N9,E9=O9,E9=P9,H9=I9,H9=J9,H9=K9,H9=L9,H9=M9,H9=N9,H9=O9,H9=P9,I9=J9,I9=K9,I9=L9,I9=M9,I9=N9,I9=O9,I9=P9,J9=K9,J9=L9,J9=M9,J9=N9,J9=O9,J9=P9,K9=L9,K9=M9,K9=N9,K9=O9,K9=P9,L9=M9,L9=N9,L9=O9,L9=P9,M9=N9,M9=O9,M9=P9,N9=O9,N9=P9,O9=P9),"FAIL","PASS") | W9: ='CRAWL_LOG'!B9 | X9: 10-slot panel: 7 near + 3 far; AN2/AN3 inactive from 03/09
A10: 46273 | B10: Thứ Ba | C10: Official | D10: 00:30 | E10: ='SLOT_RULES'!$D$4+IF($A10<='SLOT_RULES'!$D$4,0,INT(($A10-'SLOT_RULES'!$D$4-1)/'SLOT_RULES'!$E$4)+1)*'SLOT_RULES'!$E$4 | H10: ='SLOT_RULES'!$D$7+IF($A10<='SLOT_RULES'!$D$7,0,INT(($A10-'SLOT_RULES'!$D$7-1)/'SLOT_RULES'!$E$7)+1)*'SLOT_RULES'!$E$7 | I10: ='SLOT_RULES'!$D$8+IF($A10<='SLOT_RULES'!$D$8,0,INT(($A10-'SLOT_RULES'!$D$8-1)/'SLOT_RULES'!$E$8)+1)*'SLOT_RULES'!$E$8 | J10: ='SLOT_RULES'!$D$9+IF($A10<='SLOT_RULES'!$D$9,0,INT(($A10-'SLOT_RULES'!$D$9-1)/'SLOT_RULES'!$E$9)+1)*'SLOT_RULES'!$E$9 | K10: ='SLOT_RULES'!$D$10+IF($A10<='SLOT_RULES'!$D$10,0,INT(($A10-'SLOT_RULES'!$D$10-1)/'SLOT_RULES'!$E$10)+1)*'SLOT_RULES'!$E$10 | L10: ='SLOT_RULES'!$D$11+IF($A10<='SLOT_RULES'!$D$11,0,INT(($A10-'SLOT_RULES'!$D$11-1)/'SLOT_RULES'!$E$11)+1)*'SLOT_RULES'!$E$11 | M10: ='SLOT_RULES'!$D$12+IF($A10<='SLOT_RULES'!$D$12,0,INT(($A10-'SLOT_RULES'!$D$12-1)/'SLOT_RULES'!$E$12)+1)*'SLOT_RULES'!$E$12 | N10: ='SLOT_RULES'!$D$13+IF($A10<='SLOT_RULES'!$D$13,0,INT(($A10-'SLOT_RULES'!$D$13-1)/'SLOT_RULES'!$E$13)+1)*'SLOT_RULES'!$E$13 | O10: ='SLOT_RULES'!$D$14+IF($A10<='SLOT_RULES'!$D$14,0,INT(($A10-'SLOT_RULES'!$D$14-1)/'SLOT_RULES'!$E$14)+1)*'SLOT_RULES'!$E$14 | P10: ='SLOT_RULES'!$D$15+IF($A10<='SLOT_RULES'!$D$15,0,INT(($A10-'SLOT_RULES'!$D$15-1)/'SLOT_RULES'!$E$15)+1)*'SLOT_RULES'!$E$15 | Q10: =MIN(E10:P10)-A10 | R10: =MAX(E10:P10)-A10 | S10: =IF(AND(COUNT(E10:P10)=10,MIN(E10:P10)>=A10),"PASS","FAIL") | T10: =IF((COUNTIF('LOCAL_REFERENCE'!$D10:$O10,E10)+COUNTIF('LOCAL_REFERENCE'!$D10:$O10,H10)+COUNTIF('LOCAL_REFERENCE'!$D10:$O10,I10)+COUNTIF('LOCAL_REFERENCE'!$D10:$O10,J10)+COUNTIF('LOCAL_REFERENCE'!$D10:$O10,K10)+COUNTIF('LOCAL_REFERENCE'!$D10:$O10,L10)+COUNTIF('LOCAL_REFERENCE'!$D10:$O10,M10)+COUNTIF('LOCAL_REFERENCE'!$D10:$O10,N10)+COUNTIF('LOCAL_REFERENCE'!$D10:$O10,O10)+COUNTIF('LOCAL_REFERENCE'!$D10:$O10,P10))=0,"PASS","FAIL") | U10: =IF((COUNTIF('VPS_REFERENCE'!$D10:$H10,E10)+COUNTIF('VPS_REFERENCE'!$D10:$H10,H10)+COUNTIF('VPS_REFERENCE'!$D10:$H10,I10)+COUNTIF('VPS_REFERENCE'!$D10:$H10,J10)+COUNTIF('VPS_REFERENCE'!$D10:$H10,K10)+COUNTIF('VPS_REFERENCE'!$D10:$H10,L10)+COUNTIF('VPS_REFERENCE'!$D10:$H10,M10)+COUNTIF('VPS_REFERENCE'!$D10:$H10,N10)+COUNTIF('VPS_REFERENCE'!$D10:$H10,O10)+COUNTIF('VPS_REFERENCE'!$D10:$H10,P10))=0,"PASS","FAIL") | V10: =IF(OR(E10=H10,E10=I10,E10=J10,E10=K10,E10=L10,E10=M10,E10=N10,E10=O10,E10=P10,H10=I10,H10=J10,H10=K10,H10=L10,H10=M10,H10=N10,H10=O10,H10=P10,I10=J10,I10=K10,I10=L10,I10=M10,I10=N10,I10=O10,I10=P10,J10=K10,J10=L10,J10=M10,J10=N10,J10=O10,J10=P10,K10=L10,K10=M10,K10=N10,K10=O10,K10=P10,L10=M10,L10=N10,L10=O10,L10=P10,M10=N10,M10=O10,M10=P10,N10=O10,N10=P10,O10=P10),"FAIL","PASS") | W10: ='CRAWL_LOG'!B10 | X10: 10-slot panel: 7 near + 3 far; AN2/AN3 inactive from 03/09
A11: 46274 | B11: Thứ Tư | C11: Official | D11: 00:30 | E11: ='SLOT_RULES'!$D$4+IF($A11<='SLOT_RULES'!$D$4,0,INT(($A11-'SLOT_RULES'!$D$4-1)/'SLOT_RULES'!$E$4)+1)*'SLOT_RULES'!$E$4 | H11: ='SLOT_RULES'!$D$7+IF($A11<='SLOT_RULES'!$D$7,0,INT(($A11-'SLOT_RULES'!$D$7-1)/'SLOT_RULES'!$E$7)+1)*'SLOT_RULES'!$E$7 | I11: ='SLOT_RULES'!$D$8+IF($A11<='SLOT_RULES'!$D$8,0,INT(($A11-'SLOT_RULES'!$D$8-1)/'SLOT_RULES'!$E$8)+1)*'SLOT_RULES'!$E$8 | J11: ='SLOT_RULES'!$D$9+IF($A11<='SLOT_RULES'!$D$9,0,INT(($A11-'SLOT_RULES'!$D$9-1)/'SLOT_RULES'!$E$9)+1)*'SLOT_RULES'!$E$9 | K11: ='SLOT_RULES'!$D$10+IF($A11<='SLOT_RULES'!$D$10,0,INT(($A11-'SLOT_RULES'!$D$10-1)/'SLOT_RULES'!$E$10)+1)*'SLOT_RULES'!$E$10 | L11: ='SLOT_RULES'!$D$11+IF($A11<='SLOT_RULES'!$D$11,0,INT(($A11-'SLOT_RULES'!$D$11-1)/'SLOT_RULES'!$E$11)+1)*'SLOT_RULES'!$E$11 | M11: ='SLOT_RULES'!$D$12+IF($A11<='SLOT_RULES'!$D$12,0,INT(($A11-'SLOT_RULES'!$D$12-1)/'SLOT_RULES'!$E$12)+1)*'SLOT_RULES'!$E$12 | N11: ='SLOT_RULES'!$D$13+IF($A11<='SLOT_RULES'!$D$13,0,INT(($A11-'SLOT_RULES'!$D$13-1)/'SLOT_RULES'!$E$13)+1)*'SLOT_RULES'!$E$13 | O11: ='SLOT_RULES'!$D$14+IF($A11<='SLOT_RULES'!$D$14,0,INT(($A11-'SLOT_RULES'!$D$14-1)/'SLOT_RULES'!$E$14)+1)*'SLOT_RULES'!$E$14 | P11: ='SLOT_RULES'!$D$15+IF($A11<='SLOT_RULES'!$D$15,0,INT(($A11-'SLOT_RULES'!$D$15-1)/'SLOT_RULES'!$E$15)+1)*'SLOT_RULES'!$E$15 | Q11: =MIN(E11:P11)-A11 | R11: =MAX(E11:P11)-A11 | S11: =IF(AND(COUNT(E11:P11)=10,MIN(E11:P11)>=A11),"PASS","FAIL") | T11: =IF((COUNTIF('LOCAL_REFERENCE'!$D11:$O11,E11)+COUNTIF('LOCAL_REFERENCE'!$D11:$O11,H11)+COUNTIF('LOCAL_REFERENCE'!$D11:$O11,I11)+COUNTIF('LOCAL_REFERENCE'!$D11:$O11,J11)+COUNTIF('LOCAL_REFERENCE'!$D11:$O11,K11)+COUNTIF('LOCAL_REFERENCE'!$D11:$O11,L11)+COUNTIF('LOCAL_REFERENCE'!$D11:$O11,M11)+COUNTIF('LOCAL_REFERENCE'!$D11:$O11,N11)+COUNTIF('LOCAL_REFERENCE'!$D11:$O11,O11)+COUNTIF('LOCAL_REFERENCE'!$D11:$O11,P11))=0,"PASS","FAIL") | U11: =IF((COUNTIF('VPS_REFERENCE'!$D11:$H11,E11)+COUNTIF('VPS_REFERENCE'!$D11:$H11,H11)+COUNTIF('VPS_REFERENCE'!$D11:$H11,I11)+COUNTIF('VPS_REFERENCE'!$D11:$H11,J11)+COUNTIF('VPS_REFERENCE'!$D11:$H11,K11)+COUNTIF('VPS_REFERENCE'!$D11:$H11,L11)+COUNTIF('VPS_REFERENCE'!$D11:$H11,M11)+COUNTIF('VPS_REFERENCE'!$D11:$H11,N11)+COUNTIF('VPS_REFERENCE'!$D11:$H11,O11)+COUNTIF('VPS_REFERENCE'!$D11:$H11,P11))=0,"PASS","FAIL") | V11: =IF(OR(E11=H11,E11=I11,E11=J11,E11=K11,E11=L11,E11=M11,E11=N11,E11=O11,E11=P11,H11=I11,H11=J11,H11=K11,H11=L11,H11=M11,H11=N11,H11=O11,H11=P11,I11=J11,I11=K11,I11=L11,I11=M11,I11=N11,I11=O11,I11=P11,J11=K11,J11=L11,J11=M11,J11=N11,J11=O11,J11=P11,K11=L11,K11=M11,K11=N11,K11=O11,K11=P11,L11=M11,L11=N11,L11=O11,L11=P11,M11=N11,M11=O11,M11=P11,N11=O11,N11=P11,O11=P11),"FAIL","PASS") | W11: ='CRAWL_LOG'!B11 | X11: 10-slot panel: 7 near + 3 far; AN2/AN3 inactive from 03/09
A12: 46275 | B12: Thứ Năm | C12: Official | D12: 00:30 | E12: ='SLOT_RULES'!$D$4+IF($A12<='SLOT_RULES'!$D$4,0,INT(($A12-'SLOT_RULES'!$D$4-1)/'SLOT_RULES'!$E$4)+1)*'SLOT_RULES'!$E$4 | H12: ='SLOT_RULES'!$D$7+IF($A12<='SLOT_RULES'!$D$7,0,INT(($A12-'SLOT_RULES'!$D$7-1)/'SLOT_RULES'!$E$7)+1)*'SLOT_RULES'!$E$7 | I12: ='SLOT_RULES'!$D$8+IF($A12<='SLOT_RULES'!$D$8,0,INT(($A12-'SLOT_RULES'!$D$8-1)/'SLOT_RULES'!$E$8)+1)*'SLOT_RULES'!$E$8 | J12: ='SLOT_RULES'!$D$9+IF($A12<='SLOT_RULES'!$D$9,0,INT(($A12-'SLOT_RULES'!$D$9-1)/'SLOT_RULES'!$E$9)+1)*'SLOT_RULES'!$E$9 | K12: ='SLOT_RULES'!$D$10+IF($A12<='SLOT_RULES'!$D$10,0,INT(($A12-'SLOT_RULES'!$D$10-1)/'SLOT_RULES'!$E$10)+1)*'SLOT_RULES'!$E$10 | L12: ='SLOT_RULES'!$D$11+IF($A12<='SLOT_RULES'!$D$11,0,INT(($A12-'SLOT_RULES'!$D$11-1)/'SLOT_RULES'!$E$11)+1)*'SLOT_RULES'!$E$11 | M12: ='SLOT_RULES'!$D$12+IF($A12<='SLOT_RULES'!$D$12,0,INT(($A12-'SLOT_RULES'!$D$12-1)/'SLOT_RULES'!$E$12)+1)*'SLOT_RULES'!$E$12 | N12: ='SLOT_RULES'!$D$13+IF($A12<='SLOT_RULES'!$D$13,0,INT(($A12-'SLOT_RULES'!$D$13-1)/'SLOT_RULES'!$E$13)+1)*'SLOT_RULES'!$E$13 | O12: ='SLOT_RULES'!$D$14+IF($A12<='SLOT_RULES'!$D$14,0,INT(($A12-'SLOT_RULES'!$D$14-1)/'SLOT_RULES'!$E$14)+1)*'SLOT_RULES'!$E$14 | P12: ='SLOT_RULES'!$D$15+IF($A12<='SLOT_RULES'!$D$15,0,INT(($A12-'SLOT_RULES'!$D$15-1)/'SLOT_RULES'!$E$15)+1)*'SLOT_RULES'!$E$15 | Q12: =MIN(E12:P12)-A12 | R12: =MAX(E12:P12)-A12 | S12: =IF(AND(COUNT(E12:P12)=10,MIN(E12:P12)>=A12),"PASS","FAIL") | T12: =IF((COUNTIF('LOCAL_REFERENCE'!$D12:$O12,E12)+COUNTIF('LOCAL_REFERENCE'!$D12:$O12,H12)+COUNTIF('LOCAL_REFERENCE'!$D12:$O12,I12)+COUNTIF('LOCAL_REFERENCE'!$D12:$O12,J12)+COUNTIF('LOCAL_REFERENCE'!$D12:$O12,K12)+COUNTIF('LOCAL_REFERENCE'!$D12:$O12,L12)+COUNTIF('LOCAL_REFERENCE'!$D12:$O12,M12)+COUNTIF('LOCAL_REFERENCE'!$D12:$O12,N12)+COUNTIF('LOCAL_REFERENCE'!$D12:$O12,O12)+COUNTIF('LOCAL_REFERENCE'!$D12:$O12,P12))=0,"PASS","FAIL") | U12: =IF((COUNTIF('VPS_REFERENCE'!$D12:$H12,E12)+COUNTIF('VPS_REFERENCE'!$D12:$H12,H12)+COUNTIF('VPS_REFERENCE'!$D12:$H12,I12)+COUNTIF('VPS_REFERENCE'!$D12:$H12,J12)+COUNTIF('VPS_REFERENCE'!$D12:$H12,K12)+COUNTIF('VPS_REFERENCE'!$D12:$H12,L12)+COUNTIF('VPS_REFERENCE'!$D12:$H12,M12)+COUNTIF('VPS_REFERENCE'!$D12:$H12,N12)+COUNTIF('VPS_REFERENCE'!$D12:$H12,O12)+COUNTIF('VPS_REFERENCE'!$D12:$H12,P12))=0,"PASS","FAIL") | V12: =IF(OR(E12=H12,E12=I12,E12=J12,E12=K12,E12=L12,E12=M12,E12=N12,E12=O12,E12=P12,H12=I12,H12=J12,H12=K12,H12=L12,H12=M12,H12=N12,H12=O12,H12=P12,I12=J12,I12=K12,I12=L12,I12=M12,I12=N12,I12=O12,I12=P12,J12=K12,J12=L12,J12=M12,J12=N12,J12=O12,J12=P12,K12=L12,K12=M12,K12=N12,K12=O12,K12=P12,L12=M12,L12=N12,L12=O12,L12=P12,M12=N12,M12=O12,M12=P12,N12=O12,N12=P12,O12=P12),"FAIL","PASS") | W12: ='CRAWL_LOG'!B12 | X12: 10-slot panel: 7 near + 3 far; AN2/AN3 inactive from 03/09
A13: 46276 | B13: Thứ Sáu | C13: Official | D13: 00:30 | E13: ='SLOT_RULES'!$D$4+IF($A13<='SLOT_RULES'!$D$4,0,INT(($A13-'SLOT_RULES'!$D$4-1)/'SLOT_RULES'!$E$4)+1)*'SLOT_RULES'!$E$4 | H13: ='SLOT_RULES'!$D$7+IF($A13<='SLOT_RULES'!$D$7,0,INT(($A13-'SLOT_RULES'!$D$7-1)/'SLOT_RULES'!$E$7)+1)*'SLOT_RULES'!$E$7 | I13: ='SLOT_RULES'!$D$8+IF($A13<='SLOT_RULES'!$D$8,0,INT(($A13-'SLOT_RULES'!$D$8-1)/'SLOT_RULES'!$E$8)+1)*'SLOT_RULES'!$E$8 | J13: ='SLOT_RULES'!$D$9+IF($A13<='SLOT_RULES'!$D$9,0,INT(($A13-'SLOT_RULES'!$D$9-1)/'SLOT_RULES'!$E$9)+1)*'SLOT_RULES'!$E$9 | K13: ='SLOT_RULES'!$D$10+IF($A13<='SLOT_RULES'!$D$10,0,INT(($A13-'SLOT_RULES'!$D$10-1)/'SLOT_RULES'!$E$10)+1)*'SLOT_RULES'!$E$10 | L13: ='SLOT_RULES'!$D$11+IF($A13<='SLOT_RULES'!$D$11,0,INT(($A13-'SLOT_RULES'!$D$11-1)/'SLOT_RULES'!$E$11)+1)*'SLOT_RULES'!$E$11 | M13: ='SLOT_RULES'!$D$12+IF($A13<='SLOT_RULES'!$D$12,0,INT(($A13-'SLOT_RULES'!$D$12-1)/'SLOT_RULES'!$E$12)+1)*'SLOT_RULES'!$E$12 | N13: ='SLOT_RULES'!$D$13+IF($A13<='SLOT_RULES'!$D$13,0,INT(($A13-'SLOT_RULES'!$D$13-1)/'SLOT_RULES'!$E$13)+1)*'SLOT_RULES'!$E$13 | O13: ='SLOT_RULES'!$D$14+IF($A13<='SLOT_RULES'!$D$14,0,INT(($A13-'SLOT_RULES'!$D$14-1)/'SLOT_RULES'!$E$14)+1)*'SLOT_RULES'!$E$14 | P13: ='SLOT_RULES'!$D$15+IF($A13<='SLOT_RULES'!$D$15,0,INT(($A13-'SLOT_RULES'!$D$15-1)/'SLOT_RULES'!$E$15)+1)*'SLOT_RULES'!$E$15 | Q13: =MIN(E13:P13)-A13 | R13: =MAX(E13:P13)-A13 | S13: =IF(AND(COUNT(E13:P13)=10,MIN(E13:P13)>=A13),"PASS","FAIL") | T13: =IF((COUNTIF('LOCAL_REFERENCE'!$D13:$O13,E13)+COUNTIF('LOCAL_REFERENCE'!$D13:$O13,H13)+COUNTIF('LOCAL_REFERENCE'!$D13:$O13,I13)+COUNTIF('LOCAL_REFERENCE'!$D13:$O13,J13)+COUNTIF('LOCAL_REFERENCE'!$D13:$O13,K13)+COUNTIF('LOCAL_REFERENCE'!$D13:$O13,L13)+COUNTIF('LOCAL_REFERENCE'!$D13:$O13,M13)+COUNTIF('LOCAL_REFERENCE'!$D13:$O13,N13)+COUNTIF('LOCAL_REFERENCE'!$D13:$O13,O13)+COUNTIF('LOCAL_REFERENCE'!$D13:$O13,P13))=0,"PASS","FAIL") | U13: =IF((COUNTIF('VPS_REFERENCE'!$D13:$H13,E13)+COUNTIF('VPS_REFERENCE'!$D13:$H13,H13)+COUNTIF('VPS_REFERENCE'!$D13:$H13,I13)+COUNTIF('VPS_REFERENCE'!$D13:$H13,J13)+COUNTIF('VPS_REFERENCE'!$D13:$H13,K13)+COUNTIF('VPS_REFERENCE'!$D13:$H13,L13)+COUNTIF('VPS_REFERENCE'!$D13:$H13,M13)+COUNTIF('VPS_REFERENCE'!$D13:$H13,N13)+COUNTIF('VPS_REFERENCE'!$D13:$H13,O13)+COUNTIF('VPS_REFERENCE'!$D13:$H13,P13))=0,"PASS","FAIL") | V13: =IF(OR(E13=H13,E13=I13,E13=J13,E13=K13,E13=L13,E13=M13,E13=N13,E13=O13,E13=P13,H13=I13,H13=J13,H13=K13,H13=L13,H13=M13,H13=N13,H13=O13,H13=P13,I13=J13,I13=K13,I13=L13,I13=M13,I13=N13,I13=O13,I13=P13,J13=K13,J13=L13,J13=M13,J13=N13,J13=O13,J13=P13,K13=L13,K13=M13,K13=N13,K13=O13,K13=P13,L13=M13,L13=N13,L13=O13,L13=P13,M13=N13,M13=O13,M13=P13,N13=O13,N13=P13,O13=P13),"FAIL","PASS") | W13: ='CRAWL_LOG'!B13 | X13: 10-slot panel: 7 near + 3 far; AN2/AN3 inactive from 03/09
A14: 46277 | B14: Thứ Bảy | C14: Official | D14: 00:30 | E14: ='SLOT_RULES'!$D$4+IF($A14<='SLOT_RULES'!$D$4,0,INT(($A14-'SLOT_RULES'!$D$4-1)/'SLOT_RULES'!$E$4)+1)*'SLOT_RULES'!$E$4 | H14: ='SLOT_RULES'!$D$7+IF($A14<='SLOT_RULES'!$D$7,0,INT(($A14-'SLOT_RULES'!$D$7-1)/'SLOT_RULES'!$E$7)+1)*'SLOT_RULES'!$E$7 | I14: ='SLOT_RULES'!$D$8+IF($A14<='SLOT_RULES'!$D$8,0,INT(($A14-'SLOT_RULES'!$D$8-1)/'SLOT_RULES'!$E$8)+1)*'SLOT_RULES'!$E$8 | J14: ='SLOT_RULES'!$D$9+IF($A14<='SLOT_RULES'!$D$9,0,INT(($A14-'SLOT_RULES'!$D$9-1)/'SLOT_RULES'!$E$9)+1)*'SLOT_RULES'!$E$9 | K14: ='SLOT_RULES'!$D$10+IF($A14<='SLOT_RULES'!$D$10,0,INT(($A14-'SLOT_RULES'!$D$10-1)/'SLOT_RULES'!$E$10)+1)*'SLOT_RULES'!$E$10 | L14: ='SLOT_RULES'!$D$11+IF($A14<='SLOT_RULES'!$D$11,0,INT(($A14-'SLOT_RULES'!$D$11-1)/'SLOT_RULES'!$E$11)+1)*'SLOT_RULES'!$E$11 | M14: ='SLOT_RULES'!$D$12+IF($A14<='SLOT_RULES'!$D$12,0,INT(($A14-'SLOT_RULES'!$D$12-1)/'SLOT_RULES'!$E$12)+1)*'SLOT_RULES'!$E$12 | N14: ='SLOT_RULES'!$D$13+IF($A14<='SLOT_RULES'!$D$13,0,INT(($A14-'SLOT_RULES'!$D$13-1)/'SLOT_RULES'!$E$13)+1)*'SLOT_RULES'!$E$13 | O14: ='SLOT_RULES'!$D$14+IF($A14<='SLOT_RULES'!$D$14,0,INT(($A14-'SLOT_RULES'!$D$14-1)/'SLOT_RULES'!$E$14)+1)*'SLOT_RULES'!$E$14 | P14: ='SLOT_RULES'!$D$15+IF($A14<='SLOT_RULES'!$D$15,0,INT(($A14-'SLOT_RULES'!$D$15-1)/'SLOT_RULES'!$E$15)+1)*'SLOT_RULES'!$E$15 | Q14: =MIN(E14:P14)-A14 | R14: =MAX(E14:P14)-A14 | S14: =IF(AND(COUNT(E14:P14)=10,MIN(E14:P14)>=A14),"PASS","FAIL") | T14: =IF((COUNTIF('LOCAL_REFERENCE'!$D14:$O14,E14)+COUNTIF('LOCAL_REFERENCE'!$D14:$O14,H14)+COUNTIF('LOCAL_REFERENCE'!$D14:$O14,I14)+COUNTIF('LOCAL_REFERENCE'!$D14:$O14,J14)+COUNTIF('LOCAL_REFERENCE'!$D14:$O14,K14)+COUNTIF('LOCAL_REFERENCE'!$D14:$O14,L14)+COUNTIF('LOCAL_REFERENCE'!$D14:$O14,M14)+COUNTIF('LOCAL_REFERENCE'!$D14:$O14,N14)+COUNTIF('LOCAL_REFERENCE'!$D14:$O14,O14)+COUNTIF('LOCAL_REFERENCE'!$D14:$O14,P14))=0,"PASS","FAIL") | U14: =IF((COUNTIF('VPS_REFERENCE'!$D14:$H14,E14)+COUNTIF('VPS_REFERENCE'!$D14:$H14,H14)+COUNTIF('VPS_REFERENCE'!$D14:$H14,I14)+COUNTIF('VPS_REFERENCE'!$D14:$H14,J14)+COUNTIF('VPS_REFERENCE'!$D14:$H14,K14)+COUNTIF('VPS_REFERENCE'!$D14:$H14,L14)+COUNTIF('VPS_REFERENCE'!$D14:$H14,M14)+COUNTIF('VPS_REFERENCE'!$D14:$H14,N14)+COUNTIF('VPS_REFERENCE'!$D14:$H14,O14)+COUNTIF('VPS_REFERENCE'!$D14:$H14,P14))=0,"PASS","FAIL") | V14: =IF(OR(E14=H14,E14=I14,E14=J14,E14=K14,E14=L14,E14=M14,E14=N14,E14=O14,E14=P14,H14=I14,H14=J14,H14=K14,H14=L14,H14=M14,H14=N14,H14=O14,H14=P14,I14=J14,I14=K14,I14=L14,I14=M14,I14=N14,I14=O14,I14=P14,J14=K14,J14=L14,J14=M14,J14=N14,J14=O14,J14=P14,K14=L14,K14=M14,K14=N14,K14=O14,K14=P14,L14=M14,L14=N14,L14=O14,L14=P14,M14=N14,M14=O14,M14=P14,N14=O14,N14=P14,O14=P14),"FAIL","PASS") | W14: ='CRAWL_LOG'!B14 | X14: 10-slot panel: 7 near + 3 far; AN2/AN3 inactive from 03/09
A15: 46278 | B15: Chủ Nhật | C15: Official | D15: 00:30 | E15: ='SLOT_RULES'!$D$4+IF($A15<='SLOT_RULES'!$D$4,0,INT(($A15-'SLOT_RULES'!$D$4-1)/'SLOT_RULES'!$E$4)+1)*'SLOT_RULES'!$E$4 | H15: ='SLOT_RULES'!$D$7+IF($A15<='SLOT_RULES'!$D$7,0,INT(($A15-'SLOT_RULES'!$D$7-1)/'SLOT_RULES'!$E$7)+1)*'SLOT_RULES'!$E$7 | I15: ='SLOT_RULES'!$D$8+IF($A15<='SLOT_RULES'!$D$8,0,INT(($A15-'SLOT_RULES'!$D$8-1)/'SLOT_RULES'!$E$8)+1)*'SLOT_RULES'!$E$8 | J15: ='SLOT_RULES'!$D$9+IF($A15<='SLOT_RULES'!$D$9,0,INT(($A15-'SLOT_RULES'!$D$9-1)/'SLOT_RULES'!$E$9)+1)*'SLOT_RULES'!$E$9 | K15: ='SLOT_RULES'!$D$10+IF($A15<='SLOT_RULES'!$D$10,0,INT(($A15-'SLOT_RULES'!$D$10-1)/'SLOT_RULES'!$E$10)+1)*'SLOT_RULES'!$E$10 | L15: ='SLOT_RULES'!$D$11+IF($A15<='SLOT_RULES'!$D$11,0,INT(($A15-'SLOT_RULES'!$D$11-1)/'SLOT_RULES'!$E$11)+1)*'SLOT_RULES'!$E$11 | M15: ='SLOT_RULES'!$D$12+IF($A15<='SLOT_RULES'!$D$12,0,INT(($A15-'SLOT_RULES'!$D$12-1)/'SLOT_RULES'!$E$12)+1)*'SLOT_RULES'!$E$12 | N15: ='SLOT_RULES'!$D$13+IF($A15<='SLOT_RULES'!$D$13,0,INT(($A15-'SLOT_RULES'!$D$13-1)/'SLOT_RULES'!$E$13)+1)*'SLOT_RULES'!$E$13 | O15: ='SLOT_RULES'!$D$14+IF($A15<='SLOT_RULES'!$D$14,0,INT(($A15-'SLOT_RULES'!$D$14-1)/'SLOT_RULES'!$E$14)+1)*'SLOT_RULES'!$E$14 | P15: ='SLOT_RULES'!$D$15+IF($A15<='SLOT_RULES'!$D$15,0,INT(($A15-'SLOT_RULES'!$D$15-1)/'SLOT_RULES'!$E$15)+1)*'SLOT_RULES'!$E$15 | Q15: =MIN(E15:P15)-A15 | R15: =MAX(E15:P15)-A15 | S15: =IF(AND(COUNT(E15:P15)=10,MIN(E15:P15)>=A15),"PASS","FAIL") | T15: =IF((COUNTIF('LOCAL_REFERENCE'!$D15:$O15,E15)+COUNTIF('LOCAL_REFERENCE'!$D15:$O15,H15)+COUNTIF('LOCAL_REFERENCE'!$D15:$O15,I15)+COUNTIF('LOCAL_REFERENCE'!$D15:$O15,J15)+COUNTIF('LOCAL_REFERENCE'!$D15:$O15,K15)+COUNTIF('LOCAL_REFERENCE'!$D15:$O15,L15)+COUNTIF('LOCAL_REFERENCE'!$D15:$O15,M15)+COUNTIF('LOCAL_REFERENCE'!$D15:$O15,N15)+COUNTIF('LOCAL_REFERENCE'!$D15:$O15,O15)+COUNTIF('LOCAL_REFERENCE'!$D15:$O15,P15))=0,"PASS","FAIL") | U15: =IF((COUNTIF('VPS_REFERENCE'!$D15:$H15,E15)+COUNTIF('VPS_REFERENCE'!$D15:$H15,H15)+COUNTIF('VPS_REFERENCE'!$D15:$H15,I15)+COUNTIF('VPS_REFERENCE'!$D15:$H15,J15)+COUNTIF('VPS_REFERENCE'!$D15:$H15,K15)+COUNTIF('VPS_REFERENCE'!$D15:$H15,L15)+COUNTIF('VPS_REFERENCE'!$D15:$H15,M15)+COUNTIF('VPS_REFERENCE'!$D15:$H15,N15)+COUNTIF('VPS_REFERENCE'!$D15:$H15,O15)+COUNTIF('VPS_REFERENCE'!$D15:$H15,P15))=0,"PASS","FAIL") | V15: =IF(OR(E15=H15,E15=I15,E15=J15,E15=K15,E15=L15,E15=M15,E15=N15,E15=O15,E15=P15,H15=I15,H15=J15,H15=K15,H15=L15,H15=M15,H15=N15,H15=O15,H15=P15,I15=J15,I15=K15,I15=L15,I15=M15,I15=N15,I15=O15,I15=P15,J15=K15,J15=L15,J15=M15,J15=N15,J15=O15,J15=P15,K15=L15,K15=M15,K15=N15,K15=O15,K15=P15,L15=M15,L15=N15,L15=O15,L15=P15,M15=N15,M15=O15,M15=P15,N15=O15,N15=P15,O15=P15),"FAIL","PASS") | W15: ='CRAWL_LOG'!B15 | X15: 10-slot panel: 7 near + 3 far; AN2/AN3 inactive from 03/09
A16: 46279 | B16: Thứ Hai | C16: Official | D16: 00:30 | E16: ='SLOT_RULES'!$D$4+IF($A16<='SLOT_RULES'!$D$4,0,INT(($A16-'SLOT_RULES'!$D$4-1)/'SLOT_RULES'!$E$4)+1)*'SLOT_RULES'!$E$4 | H16: ='SLOT_RULES'!$D$7+IF($A16<='SLOT_RULES'!$D$7,0,INT(($A16-'SLOT_RULES'!$D$7-1)/'SLOT_RULES'!$E$7)+1)*'SLOT_RULES'!$E$7 | I16: ='SLOT_RULES'!$D$8+IF($A16<='SLOT_RULES'!$D$8,0,INT(($A16-'SLOT_RULES'!$D$8-1)/'SLOT_RULES'!$E$8)+1)*'SLOT_RULES'!$E$8 | J16: ='SLOT_RULES'!$D$9+IF($A16<='SLOT_RULES'!$D$9,0,INT(($A16-'SLOT_RULES'!$D$9-1)/'SLOT_RULES'!$E$9)+1)*'SLOT_RULES'!$E$9 | K16: ='SLOT_RULES'!$D$10+IF($A16<='SLOT_RULES'!$D$10,0,INT(($A16-'SLOT_RULES'!$D$10-1)/'SLOT_RULES'!$E$10)+1)*'SLOT_RULES'!$E$10 | L16: ='SLOT_RULES'!$D$11+IF($A16<='SLOT_RULES'!$D$11,0,INT(($A16-'SLOT_RULES'!$D$11-1)/'SLOT_RULES'!$E$11)+1)*'SLOT_RULES'!$E$11 | M16: ='SLOT_RULES'!$D$12+IF($A16<='SLOT_RULES'!$D$12,0,INT(($A16-'SLOT_RULES'!$D$12-1)/'SLOT_RULES'!$E$12)+1)*'SLOT_RULES'!$E$12 | N16: ='SLOT_RULES'!$D$13+IF($A16<='SLOT_RULES'!$D$13,0,INT(($A16-'SLOT_RULES'!$D$13-1)/'SLOT_RULES'!$E$13)+1)*'SLOT_RULES'!$E$13 | O16: ='SLOT_RULES'!$D$14+IF($A16<='SLOT_RULES'!$D$14,0,INT(($A16-'SLOT_RULES'!$D$14-1)/'SLOT_RULES'!$E$14)+1)*'SLOT_RULES'!$E$14 | P16: ='SLOT_RULES'!$D$15+IF($A16<='SLOT_RULES'!$D$15,0,INT(($A16-'SLOT_RULES'!$D$15-1)/'SLOT_RULES'!$E$15)+1)*'SLOT_RULES'!$E$15 | Q16: =MIN(E16:P16)-A16 | R16: =MAX(E16:P16)-A16 | S16: =IF(AND(COUNT(E16:P16)=10,MIN(E16:P16)>=A16),"PASS","FAIL") | T16: =IF((COUNTIF('LOCAL_REFERENCE'!$D16:$O16,E16)+COUNTIF('LOCAL_REFERENCE'!$D16:$O16,H16)+COUNTIF('LOCAL_REFERENCE'!$D16:$O16,I16)+COUNTIF('LOCAL_REFERENCE'!$D16:$O16,J16)+COUNTIF('LOCAL_REFERENCE'!$D16:$O16,K16)+COUNTIF('LOCAL_REFERENCE'!$D16:$O16,L16)+COUNTIF('LOCAL_REFERENCE'!$D16:$O16,M16)+COUNTIF('LOCAL_REFERENCE'!$D16:$O16,N16)+COUNTIF('LOCAL_REFERENCE'!$D16:$O16,O16)+COUNTIF('LOCAL_REFERENCE'!$D16:$O16,P16))=0,"PASS","FAIL") | U16: =IF((COUNTIF('VPS_REFERENCE'!$D16:$H16,E16)+COUNTIF('VPS_REFERENCE'!$D16:$H16,H16)+COUNTIF('VPS_REFERENCE'!$D16:$H16,I16)+COUNTIF('VPS_REFERENCE'!$D16:$H16,J16)+COUNTIF('VPS_REFERENCE'!$D16:$H16,K16)+COUNTIF('VPS_REFERENCE'!$D16:$H16,L16)+COUNTIF('VPS_REFERENCE'!$D16:$H16,M16)+COUNTIF('VPS_REFERENCE'!$D16:$H16,N16)+COUNTIF('VPS_REFERENCE'!$D16:$H16,O16)+COUNTIF('VPS_REFERENCE'!$D16:$H16,P16))=0,"PASS","FAIL") | V16: =IF(OR(E16=H16,E16=I16,E16=J16,E16=K16,E16=L16,E16=M16,E16=N16,E16=O16,E16=P16,H16=I16,H16=J16,H16=K16,H16=L16,H16=M16,H16=N16,H16=O16,H16=P16,I16=J16,I16=K16,I16=L16,I16=M16,I16=N16,I16=O16,I16=P16,J16=K16,J16=L16,J16=M16,J16=N16,J16=O16,J16=P16,K16=L16,K16=M16,K16=N16,K16=O16,K16=P16,L16=M16,L16=N16,L16=O16,L16=P16,M16=N16,M16=O16,M16=P16,N16=O16,N16=P16,O16=P16),"FAIL","PASS") | W16: ='CRAWL_LOG'!B16 | X16: 10-slot panel: 7 near + 3 far; AN2/AN3 inactive from 03/09
... A93: 46356 | B93: Thứ Hai | C93: Official | D93: 00:30 | E93: ='SLOT_RULES'!$D$4+IF($A93<='SLOT_RULES'!$D$4,0,INT(($A93-'SLOT_RULES'!$D$4-1)/'SLOT_RULES'!$E$4)+1)*'SLOT_RULES'!$E$4 | H93: ='SLOT_RULES'!$D$7+IF($A93<='SLOT_RULES'!$D$7,0,INT(($A93-'SLOT_RULES'!$D$7-1)/'SLOT_RULES'!$E$7)+1)*'SLOT_RULES'!$E$7 | I93: ='SLOT_RULES'!$D$8+IF($A93<='SLOT_RULES'!$D$8,0,INT(($A93-'SLOT_RULES'!$D$8-1)/'SLOT_RULES'!$E$8)+1)*'SLOT_RULES'!$E$8 | J93: ='SLOT_RULES'!$D$9+IF($A93<='SLOT_RULES'!$D$9,0,INT(($A93-'SLOT_RULES'!$D$9-1)/'SLOT_RULES'!$E$9)+1)*'SLOT_RULES'!$E$9 | K93: ='SLOT_RULES'!$D$10+IF($A93<='SLOT_RULES'!$D$10,0,INT(($A93-'SLOT_RULES'!$D$10-1)/'SLOT_RULES'!$E$10)+1)*'SLOT_RULES'!$E$10 | L93: ='SLOT_RULES'!$D$11+IF($A93<='SLOT_RULES'!$D$11,0,INT(($A93-'SLOT_RULES'!$D$11-1)/'SLOT_RULES'!$E$11)+1)*'SLOT_RULES'!$E$11 | M93: ='SLOT_RULES'!$D$12+IF($A93<='SLOT_RULES'!$D$12,0,INT(($A93-'SLOT_RULES'!$D$12-1)/'SLOT_RULES'!$E$12)+1)*'SLOT_RULES'!$E$12 | N93: ='SLOT_RULES'!$D$13+IF($A93<='SLOT_RULES'!$D$13,0,INT(($A93-'SLOT_RULES'!$D$13-1)/'SLOT_RULES'!$E$13)+1)*'SLOT_RULES'!$E$13 | O93: ='SLOT_RULES'!$D$14+IF($A93<='SLOT_RULES'!$D$14,0,INT(($A93-'SLOT_RULES'!$D$14-1)/'SLOT_RULES'!$E$14)+1)*'SLOT_RULES'!$E$14 | P93: ='SLOT_RULES'!$D$15+IF($A93<='SLOT_RULES'!$D$15,0,INT(($A93-'SLOT_RULES'!$D$15-1)/'SLOT_RULES'!$E$15)+1)*'SLOT_RULES'!$E$15 | Q93: =MIN(E93:P93)-A93 | R93: =MAX(E93:P93)-A93 | S93: =IF(AND(COUNT(E93:P93)=10,MIN(E93:P93)>=A93),"PASS","FAIL") | T93: =IF((COUNTIF('LOCAL_REFERENCE'!$D93:$O93,E93)+COUNTIF('LOCAL_REFERENCE'!$D93:$O93,H93)+COUNTIF('LOCAL_REFERENCE'!$D93:$O93,I93)+COUNTIF('LOCAL_REFERENCE'!$D93:$O93,J93)+COUNTIF('LOCAL_REFERENCE'!$D93:$O93,K93)+COUNTIF('LOCAL_REFERENCE'!$D93:$O93,L93)+COUNTIF('LOCAL_REFERENCE'!$D93:$O93,M93)+COUNTIF('LOCAL_REFERENCE'!$D93:$O93,N93)+COUNTIF('LOCAL_REFERENCE'!$D93:$O93,O93)+COUNTIF('LOCAL_REFERENCE'!$D93:$O93,P93))=0,"PASS","FAIL") | U93: =IF((COUNTIF('VPS_REFERENCE'!$D93:$H93,E93)+COUNTIF('VPS_REFERENCE'!$D93:$H93,H93)+COUNTIF('VPS_REFERENCE'!$D93:$H93,I93)+COUNTIF('VPS_REFERENCE'!$D93:$H93,J93)+COUNTIF('VPS_REFERENCE'!$D93:$H93,K93)+COUNTIF('VPS_REFERENCE'!$D93:$H93,L93)+COUNTIF('VPS_REFERENCE'!$D93:$H93,M93)+COUNTIF('VPS_REFERENCE'!$D93:$H93,N93)+COUNTIF('VPS_REFERENCE'!$D93:$H93,O93)+COUNTIF('VPS_REFERENCE'!$D93:$H93,P93))=0,"PASS","FAIL") | V93: =IF(OR(E93=H93,E93=I93,E93=J93,E93=K93,E93=L93,E93=M93,E93=N93,E93=O93,E93=P93,H93=I93,H93=J93,H93=K93,H93=L93,H93=M93,H93=N93,H93=O93,H93=P93,I93=J93,I93=K93,I93=L93,I93=M93,I93=N93,I93=O93,I93=P93,J93=K93,J93=L93,J93=M93,J93=N93,J93=O93,J93=P93,K93=L93,K93=M93,K93=N93,K93=O93,K93=P93,L93=M93,L93=N93,L93=O93,L93=P93,M93=N93,M93=O93,M93=P93,N93=O93,N93=P93,O93=P93),"FAIL","PASS") | W93: ='CRAWL_LOG'!B93 | X93: 10-slot panel: 7 near + 3 far; AN2/AN3 inactive from 03/09

Sheet CRAWL_LOG
A1: AUX-LOCAL CRAWL LOG — MỖI NGÀY MỘT DÒNG
A2: Ghi một dòng cho mỗi crawl date. Cohort v2 có 354 khách sạn: 02/09 dùng 12 check-in = 4.248 item; từ 03/09 dùng 10 check-in = 3.540 item. Không lưu HTML/ảnh nếu không cần audit.
A3: Crawl date | B3: Status | C3: Run IDs | D3: Started at | E3: Finished at | F3: Duration (hours) | G3: Total items | H3: Processed | I3: Success | J3: Partial | K3: Sold out | L3: Not bookable | M3: Error | N3: Valid records | O3: Check-in count | P3: Environment | Q3: Notes
A4: 46267 | B4: Hoàn thành có lỗi | C4: 2 | D4: 46267.047 | E4: 46268.006 | F4: =IF(AND(D4<>"",E4<>""),(E4-D4)*24,"") | G4: 4260 | H4: 4260 | I4: 3862 | J4: 0 | K4: 314 | L4: 72 | M4: 12 | N4: 35737 | O4: 12 | P4: local_aux | Q4: Scheduled run 2 completed; aggregate recovered from local_aux DB
A5: 46268 | B5: Thất bại | F5: =IF(AND(D5<>"",E5<>""),(E5-D5)*24,"") | O5: 10 | P5: local_aux | Q5: ValueError: Chỉ tạo run khi Status='Chưa chạy', hiện là 'Thất bại'
A6: 46269 | B6: Chưa chạy | F6: =IF(AND(D6<>"",E6<>""),(E6-D6)*24,"") | O6: 10 | P6: local_aux
A7: 46270 | B7: Hoàn thành có lỗi | C7: 4 | D7: 46270.022 | E7: 46270.554 | F7: =IF(AND(D7<>"",E7<>""),(E7-D7)*24,"") | G7: 2478 | H7: 2478 | I7: 2190 | J7: 0 | K7: 253 | L7: 21 | M7: 14 | N7: 20413 | O7: 7 | P7: local_aux | Q7: Scheduled run 4 terminal
A8: 46271 | B8: Hoàn thành có lỗi | C8: 5 | D8: 46271.024 | E8: 46271.844 | F8: =IF(AND(D8<>"",E8<>""),(E8-D8)*24,"") | G8: 3540 | H8: 3540 | I8: 3185 | J8: 0 | K8: 305 | L8: 30 | M8: 20 | N8: 29179 | O8: 10 | P8: local_aux | Q8: Scheduled run 5 terminal
A9: 46272 | B9: Hoàn thành có lỗi | C9: 6 | D9: 46272.025 | E9: 46272.815 | F9: =IF(AND(D9<>"",E9<>""),(E9-D9)*24,"") | G9: 3540 | H9: 3540 | I9: 3177 | J9: 0 | K9: 313 | L9: 30 | M9: 20 | N9: 28420 | O9: 10 | P9: local_aux | Q9: Scheduled run 6 terminal
A10: 46273 | B10: Hoàn thành có lỗi | C10: 7 | D10: 46273.024 | E10: 46273.821 | F10: =IF(AND(D10<>"",E10<>""),(E10-D10)*24,"") | G10: 3540 | H10: 3540 | I10: 3174 | J10: 0 | K10: 306 | L10: 40 | M10: 20 | N10: 29258 | O10: 10 | P10: local_aux | Q10: Scheduled run 7 terminal
A11: 46274 | B11: Hoàn thành có lỗi | C11: 8 | D11: 46274.026 | E11: 46275.028 | F11: =IF(AND(D11<>"",E11<>""),(E11-D11)*24,"") | G11: 3540 | H11: 3540 | I11: 3165 | J11: 0 | K11: 305 | L11: 50 | M11: 20 | N11: 29944 | O11: 10 | P11: local_aux | Q11: Scheduled run 8 terminal
A12: 46275 | B12: Hoàn thành có lỗi | C12: 9 | D12: 46275.023 | E12: 46275.837 | F12: =IF(AND(D12<>"",E12<>""),(E12-D12)*24,"") | G12: 3540 | H12: 3540 | I12: 3165 | J12: 0 | K12: 305 | L12: 50 | M12: 20 | N12: 29811 | O12: 10 | P12: local_aux | Q12: Scheduled run 9 terminal
A13: 46276 | B13: Hoàn thành có lỗi | C13: 10 | D13: 46276.024 | E13: 46276.855 | F13: =IF(AND(D13<>"",E13<>""),(E13-D13)*24,"") | G13: 3540 | H13: 3540 | I13: 3174 | J13: 0 | K13: 316 | L13: 30 | M13: 20 | N13: 30010 | O13: 10 | P13: local_aux | Q13: Scheduled run 10 terminal
A14: 46277 | B14: Hoàn thành có lỗi | C14: 11 | D14: 46277.024 | E14: 46277.835 | F14: =IF(AND(D14<>"",E14<>""),(E14-D14)*24,"") | G14: 3540 | H14: 3540 | I14: 3175 | J14: 0 | K14: 315 | L14: 30 | M14: 20 | N14: 29730 | O14: 10 | P14: local_aux | Q14: Scheduled run 11 terminal
A15: 46278 | B15: Hoàn thành có lỗi | C15: 12 | D15: 46277.732 | E15: 46278.797 | F15: =IF(AND(D15<>"",E15<>""),(E15-D15)*24,"") | G15: 3540 | H15: 3540 | I15: 3175 | J15: 0 | K15: 315 | L15: 30 | M15: 20 | N15: 29379 | O15: 10 | P15: local_aux | Q15: Scheduled run 12 terminal
A16: 46279 | B16: Hoàn thành có lỗi | C16: 13 | D16: 46278.729 | E16: 46279.906 | F16: =IF(AND(D16<>"",E16<>""),(E16-D16)*24,"") | G16: 3540 | H16: 2 | I16: 2 | O16: 10 | P16: local_aux | Q16: Bỏ qua theo yêu cầu người dùng; dừng run 13 sau 2/3540 item. Ngày kế tiếp chạy độc lập.
A17: 46280 | B17: Hoàn thành có lỗi | C17: 14 | D17: 46279.737 | E17: 46280.815 | F17: =IF(AND(D17<>"",E17<>""),(E17-D17)*24,"") | G17: 3540 | H17: 3540 | I17: 3152 | J17: 0 | K17: 328 | L17: 40 | M17: 20 | N17: 28862 | O17: 10 | P17: local_aux | Q17: Scheduled run 14 terminal
A18: 46281 | B18: Hoàn thành có lỗi | C18: 15 | D18: 46281.027 | E18: 46281.814 | F18: =IF(AND(D18<>"",E18<>""),(E18-D18)*24,"") | G18: 3540 | H18: 3540 | I18: 3170 | J18: 0 | K18: 310 | L18: 40 | M18: 20 | N18: 29084 | O18: 10 | P18: local_aux | Q18: Scheduled run 15 terminal
A19: 46282 | B19: Hoàn thành có lỗi | C19: 16 | D19: 46282.023 | E19: 46282.784 | F19: =IF(AND(D19<>"",E19<>""),(E19-D19)*24,"") | G19: 3540 | H19: 3540 | I19: 3121 | J19: 0 | K19: 309 | L19: 90 | M19: 20 | N19: 28229 | O19: 10 | P19: local_aux | Q19: Scheduled run 16 terminal
A20: 46283 | B20: Hoàn thành có lỗi | C20: 17 | D20: 46283.024 | E20: 46283.786 | F20: =IF(AND(D20<>"",E20<>""),(E20-D20)*24,"") | G20: 3540 | H20: 3540 | I20: 3133 | J20: 0 | K20: 307 | L20: 80 | M20: 20 | N20: 28008 | O20: 10 | P20: local_aux | Q20: Scheduled run 17 terminal
A21: 46284 | B21: Hoàn thành có lỗi | C21: 18 | D21: 46284.023 | E21: 46284.788 | F21: =IF(AND(D21<>"",E21<>""),(E21-D21)*24,"") | G21: 3540 | H21: 3540 | I21: 3156 | J21: 0 | K21: 314 | L21: 50 | M21: 20 | N21: 28398 | O21: 10 | P21: local_aux | Q21: Scheduled run 18 terminal
A22: 46285 | B22: Hoàn thành có lỗi | C22: 19 | D22: 46285.094 | E22: 46285.871 | F22: =IF(AND(D22<>"",E22<>""),(E22-D22)*24,"") | G22: 3540 | H22: 3540 | I22: 3140 | J22: 0 | K22: 340 | L22: 40 | M22: 20 | N22: 28144 | O22: 10 | P22: local_aux | Q22: Scheduled run 19 terminal
A23: 46286 | B23: Hoàn thành có lỗi | C23: 20 | D23: 46286.031 | E23: 46286.81 | F23: =IF(AND(D23<>"",E23<>""),(E23-D23)*24,"") | G23: 3540 | H23: 3540 | I23: 3141 | J23: 0 | K23: 329 | L23: 50 | M23: 20 | N23: 27670 | O23: 10 | P23: local_aux | Q23: Scheduled run 20 terminal
A24: 46287 | B24: Hoàn thành có lỗi | C24: 21 | D24: 46287.023 | E24: 46287.815 | F24: =IF(AND(D24<>"",E24<>""),(E24-D24)*24,"") | G24: 3540 | H24: 3540 | I24: 3149 | J24: 0 | K24: 331 | L24: 40 | M24: 20 | N24: 28858 | O24: 10 | P24: local_aux | Q24: Scheduled run 21 terminal
A25: 46288 | B25: Hoàn thành có lỗi | C25: 22 | D25: 46288.023 | E25: 46288.808 | F25: =IF(AND(D25<>"",E25<>""),(E25-D25)*24,"") | G25: 3540 | H25: 3540 | I25: 3148 | J25: 0 | K25: 342 | L25: 30 | M25: 20 | N25: 28828 | O25: 10 | P25: local_aux | Q25: Scheduled run 22 terminal
A26: 46289 | B26: Hoàn thành có lỗi | C26: 23 | D26: 46289.029 | E26: 46289.823 | F26: =IF(AND(D26<>"",E26<>""),(E26-D26)*24,"") | G26: 3540 | H26: 3540 | I26: 3093 | J26: 0 | K26: 387 | L26: 40 | M26: 20 | N26: 28165 | O26: 10 | P26: local_aux | Q26: Scheduled run 23 terminal
A27: 46290 | B27: Hoàn thành có lỗi | C27: 24 | D27: 46290.023 | E27: 46290.917 | F27: =IF(AND(D27<>"",E27<>""),(E27-D27)*24,"") | G27: 3540 | H27: 3540 | I27: 3070 | J27: 0 | K27: 410 | L27: 40 | M27: 20 | N27: 27956 | O27: 10 | P27: local_aux | Q27: Scheduled run 24 terminal
A28: 46291 | B28: Hoàn thành có lỗi | C28: 25 | D28: 46291.029 | E28: 46292.031 | F28: =IF(AND(D28<>"",E28<>""),(E28-D28)*24,"") | G28: 3540 | H28: 3540 | I28: 3091 | J28: 0 | K28: 339 | L28: 90 | M28: 20 | N28: 29386 | O28: 10 | P28: local_aux | Q28: Scheduled run 25 terminal
A29: 46292 | B29: Hoàn thành có lỗi | C29: 26 | D29: 46292.012 | E29: 46293.201 | F29: =IF(AND(D29<>"",E29<>""),(E29-D29)*24,"") | G29: 3540 | H29: 3540 | I29: 3097 | J29: 0 | K29: 323 | L29: 100 | M29: 20 | N29: 29294 | O29: 10 | P29: local_aux | Q29: Scheduled run 26 terminal
A30: 46293 | B30: Hoàn thành có lỗi | C30: 27 | E30: 46294.529 | F30: =IF(AND(D30<>"",E30<>""),(E30-D30)*24,"") | G30: 3540 | H30: 3540 | I30: 3105 | J30: 0 | K30: 315 | L30: 100 | M30: 20 | N30: 29991 | O30: 10 | P30: local_aux | Q30: Scheduled run 27 terminal
A31: 46294 | B31: Hoàn thành có lỗi | C31: 28 | D31: 46294.021 | E31: 46294.742 | F31: =IF(AND(D31<>"",E31<>""),(E31-D31)*24,"") | G31: 3540 | H31: 3540 | I31: 3109 | J31: 0 | K31: 321 | L31: 80 | M31: 30 | N31: 29923 | O31: 10 | P31: local_aux_backup | Q31: Imported as run 28; SHA-256 + staging counts verified.
A32: 46295 | B32: Hoàn thành có lỗi | C32: 29 | D32: 46295.023 | E32: 46296.439 | F32: =IF(AND(D32<>"",E32<>""),(E32-D32)*24,"") | G32: 3540 | H32: 3540 | I32: 3111 | J32: 0 | K32: 319 | L32: 80 | M32: 30 | N32: 29571 | O32: 10 | P32: local_aux | Q32: Scheduled run 29 terminal
A33: 46296 | B33: Hoàn thành có lỗi | C33: 30 | D33: 46296.063 | E33: 46296.777 | F33: =IF(AND(D33<>"",E33<>""),(E33-D33)*24,"") | G33: 3540 | H33: 3540 | I33: 3093 | J33: 0 | K33: 317 | L33: 90 | M33: 40 | N33: 29357 | O33: 10 | P33: local_aux_backup | Q33: Imported as run 30; SHA-256 + staging counts verified.
A34: 46297 | B34: Hoàn thành có lỗi | C34: 31 | D34: 46297.026 | E34: 46297.794 | F34: =IF(AND(D34<>"",E34<>""),(E34-D34)*24,"") | G34: 3540 | H34: 3540 | I34: 3085 | J34: 0 | K34: 325 | L34: 90 | M34: 40 | N34: 28852 | O34: 10 | P34: local_aux | Q34: Scheduled run 31 terminal
A35: 46298 | B35: Hoàn thành có lỗi | C35: 32 | D35: 46298.022 | E35: 46298.773 | F35: =IF(AND(D35<>"",E35<>""),(E35-D35)*24,"") | G35: 3540 | H35: 3540 | I35: 3120 | J35: 0 | K35: 280 | L35: 100 | M35: 40 | N35: 29700 | O35: 10 | P35: local_aux | Q35: Scheduled run 32 terminal
A36: 46299 | B36: Hoàn thành có lỗi | C36: 33 | D36: 46299.024 | E36: 46299.788 | F36: =IF(AND(D36<>"",E36<>""),(E36-D36)*24,"") | G36: 3540 | H36: 3540 | I36: 3114 | J36: 0 | K36: 286 | L36: 100 | M36: 40 | N36: 29355 | O36: 10 | P36: local_aux | Q36: Scheduled run 33 terminal
A37: 46300 | B37: Hoàn thành có lỗi | C37: 34 | D37: 46300.023 | E37: 46300.872 | F37: =IF(AND(D37<>"",E37<>""),(E37-D37)*24,"") | G37: 3540 | H37: 3540 | I37: 3101 | J37: 0 | K37: 289 | L37: 110 | M37: 40 | N37: 28761 | O37: 10 | P37: local_aux | Q37: Scheduled run 34 terminal
A38: 46301 | B38: Hoàn thành có lỗi | C38: 35 | D38: 46301.023 | E38: 46301.798 | F38: =IF(AND(D38<>"",E38<>""),(E38-D38)*24,"") | G38: 3540 | H38: 3540 | I38: 3075 | J38: 0 | K38: 315 | L38: 100 | M38: 50 | N38: 29087 | O38: 10 | P38: local_aux | Q38: Scheduled run 35 terminal
A39: 46302 | B39: Hoàn thành có lỗi | C39: 36 | D39: 46302.023 | E39: 46302.773 | F39: =IF(AND(D39<>"",E39<>""),(E39-D39)*24,"") | G39: 3540 | H39: 3540 | I39: 3078 | J39: 0 | K39: 312 | L39: 100 | M39: 50 | N39: 29671 | O39: 10 | P39: local_aux | Q39: Scheduled run 36 terminal
A40: 46303 | B40: Hoàn thành có lỗi | C40: 37 | D40: 46303.021 | E40: 46303.763 | F40: =IF(AND(D40<>"",E40<>""),(E40-D40)*24,"") | G40: 3540 | H40: 3540 | I40: 3056 | J40: 0 | K40: 314 | L40: 120 | M40: 50 | N40: 29442 | O40: 10 | P40: local_aux | Q40: Scheduled run 37 terminal
...

Sheet LOCAL_REFERENCE
A1: LOCAL PRIMARY REFERENCE — 12 CHECK-IN DÙNG ĐỂ LOẠI TRÙNG
A2: Nguồn: D:/MSE/CAPSTONE/outputs/crawl-data-planner-20260816/crawl_sampling_master.xlsx. Snapshot 02/09–30/11/2026; không sửa bằng tay.
A3: Crawl date | B3: Thứ | C3: Start time | D3: N1 | E3: N2 | F3: N3 | G3: N4 | H3: N5 | I3: N6 | J3: N7 | K3: N8 | L3: N9 | M3: F1 | N3: F2 | O3: F3 | P3: Source file
A4: 46267 | B4: Thứ Tư | C4: 00:30 | D4: 46282 | E4: 46284 | F4: 46287 | G4: 46291 | H4: 46267 | I4: 46271 | J4: 46274 | K4: 46277 | L4: 46279 | M4: 46306 | N4: 46344 | O4: 46388 | P4: crawl_sampling_master.xlsx
A5: 46268 | B5: Thứ Năm | C5: 00:30 | D5: 46282 | E5: 46284 | F5: 46287 | G5: 46291 | H5: 46295 | I5: 46271 | J5: 46274 | K5: 46277 | L5: 46279 | M5: 46306 | N5: 46344 | O5: 46388 | P5: crawl_sampling_master.xlsx
A6: 46269 | B6: Thứ Sáu | C6: 00:30 | D6: 46282 | E6: 46284 | F6: 46287 | G6: 46291 | H6: 46295 | I6: 46271 | J6: 46274 | K6: 46277 | L6: 46279 | M6: 46306 | N6: 46344 | O6: 46388 | P6: crawl_sampling_master.xlsx
A7: 46270 | B7: Thứ Bảy | C7: 00:30 | D7: 46282 | E7: 46284 | F7: 46287 | G7: 46291 | H7: 46295 | I7: 46271 | J7: 46274 | K7: 46277 | L7: 46279 | M7: 46306 | N7: 46344 | O7: 46388 | P7: crawl_sampling_master.xlsx
A8: 46271 | B8: Chủ Nhật | C8: 00:30 | D8: 46282 | E8: 46284 | F8: 46287 | G8: 46291 | H8: 46295 | I8: 46271 | J8: 46274 | K8: 46277 | L8: 46279 | M8: 46306 | N8: 46344 | O8: 46388 | P8: crawl_sampling_master.xlsx
A9: 46272 | B9: Thứ Hai | C9: 00:30 | D9: 46282 | E9: 46284 | F9: 46287 | G9: 46291 | H9: 46295 | I9: 46299 | J9: 46274 | K9: 46277 | L9: 46279 | M9: 46306 | N9: 46344 | O9: 46388 | P9: crawl_sampling_master.xlsx
A10: 46273 | B10: Thứ Ba | C10: 00:30 | D10: 46282 | E10: 46284 | F10: 46287 | G10: 46291 | H10: 46295 | I10: 46299 | J10: 46274 | K10: 46277 | L10: 46279 | M10: 46306 | N10: 46344 | O10: 46388 | P10: crawl_sampling_master.xlsx
A11: 46274 | B11: Thứ Tư | C11: 00:30 | D11: 46282 | E11: 46284 | F11: 46287 | G11: 46291 | H11: 46295 | I11: 46299 | J11: 46274 | K11: 46277 | L11: 46279 | M11: 46306 | N11: 46344 | O11: 46388 | P11: crawl_sampling_master.xlsx
A12: 46275 | B12: Thứ Năm | C12: 00:30 | D12: 46282 | E12: 46284 | F12: 46287 | G12: 46291 | H12: 46295 | I12: 46299 | J12: 46302 | K12: 46277 | L12: 46279 | M12: 46306 | N12: 46344 | O12: 46388 | P12: crawl_sampling_master.xlsx
A13: 46276 | B13: Thứ Sáu | C13: 00:30 | D13: 46282 | E13: 46284 | F13: 46287 | G13: 46291 | H13: 46295 | I13: 46299 | J13: 46302 | K13: 46277 | L13: 46279 | M13: 46306 | N13: 46344 | O13: 46388 | P13: crawl_sampling_master.xlsx
A14: 46277 | B14: Thứ Bảy | C14: 00:30 | D14: 46282 | E14: 46284 | F14: 46287 | G14: 46291 | H14: 46295 | I14: 46299 | J14: 46302 | K14: 46277 | L14: 46279 | M14: 46306 | N14: 46344 | O14: 46388 | P14: crawl_sampling_master.xlsx
A15: 46278 | B15: Chủ Nhật | C15: 00:30 | D15: 46282 | E15: 46284 | F15: 46287 | G15: 46291 | H15: 46295 | I15: 46299 | J15: 46302 | K15: 46305 | L15: 46279 | M15: 46306 | N15: 46344 | O15: 46388 | P15: crawl_sampling_master.xlsx
... A93: 46356 | B93: Thứ Hai | C93: 00:30 | D93: 46366 | E93: 46368 | F93: 46371 | G93: 46375 | H93: 46379 | I93: 46383 | J93: 46358 | K93: 46361 | L93: 46363 | M93: 46362 | N93: 46428 | O93: 46388 | P93: crawl_sampling_master.xlsx

Sheet VPS_REFERENCE
A1: VPS REFERENCE — 5 CHECK-IN DÙNG ĐỂ LOẠI TRÙNG
A2: Nguồn: D:/MSE/CAPSTONE/outputs/vps-crawl-planner-20260823/vps_crawl_sampling_master.xlsx. Snapshot 02/09–30/11/2026; không sửa bằng tay.
A3: Crawl date | B3: Thứ | C3: Start time | D3: V1 | E3: V2 | F3: V3 | G3: V4 | H3: V5 | I3: Source file
A4: 46267 | B4: Thứ Tư | C4: 00:30 | D4: 46289 | E4: 46292 | F4: 46268 | G4: 46281 | H4: 46411 | I4: vps_crawl_sampling_master.xlsx
A5: 46268 | B5: Thứ Năm | C5: 00:30 | D5: 46289 | E5: 46292 | F5: 46268 | G5: 46281 | H5: 46411 | I5: vps_crawl_sampling_master.xlsx
A6: 46269 | B6: Thứ Sáu | C6: 00:30 | D6: 46289 | E6: 46292 | F6: 46296 | G6: 46281 | H6: 46411 | I6: vps_crawl_sampling_master.xlsx
A7: 46270 | B7: Thứ Bảy | C7: 00:30 | D7: 46289 | E7: 46292 | F7: 46296 | G7: 46281 | H7: 46411 | I7: vps_crawl_sampling_master.xlsx
A8: 46271 | B8: Chủ Nhật | C8: 00:30 | D8: 46289 | E8: 46292 | F8: 46296 | G8: 46281 | H8: 46411 | I8: vps_crawl_sampling_master.xlsx
A9: 46272 | B9: Thứ Hai | C9: 00:30 | D9: 46289 | E9: 46292 | F9: 46296 | G9: 46281 | H9: 46411 | I9: vps_crawl_sampling_master.xlsx
A10: 46273 | B10: Thứ Ba | C10: 00:30 | D10: 46289 | E10: 46292 | F10: 46296 | G10: 46281 | H10: 46411 | I10: vps_crawl_sampling_master.xlsx
A11: 46274 | B11: Thứ Tư | C11: 00:30 | D11: 46289 | E11: 46292 | F11: 46296 | G11: 46281 | H11: 46411 | I11: vps_crawl_sampling_master.xlsx
A12: 46275 | B12: Thứ Năm | C12: 00:30 | D12: 46289 | E12: 46292 | F12: 46296 | G12: 46281 | H12: 46411 | I12: vps_crawl_sampling_master.xlsx
A13: 46276 | B13: Thứ Sáu | C13: 00:30 | D13: 46289 | E13: 46292 | F13: 46296 | G13: 46281 | H13: 46411 | I13: vps_crawl_sampling_master.xlsx
A14: 46277 | B14: Thứ Bảy | C14: 00:30 | D14: 46289 | E14: 46292 | F14: 46296 | G14: 46281 | H14: 46411 | I14: vps_crawl_sampling_master.xlsx
A15: 46278 | B15: Chủ Nhật | C15: 00:30 | D15: 46289 | E15: 46292 | F15: 46296 | G15: 46281 | H15: 46411 | I15: vps_crawl_sampling_master.xlsx
... A93: 46356 | B93: Thứ Hai | C93: 00:30 | D93: 46373 | E93: 46376 | F93: 46380 | G93: 46365 | H93: 46411 | I93: vps_crawl_sampling_master.xlsx

Sheet SLOT_RULES
A1: QUY TẮC MÁY PHỤ — 12 SLOT NGÀY 02/09; 10 SLOT TỪ 03/09
A3: Slot | B3: Vai trò | C3: Mục đích | D3: Anchor đầu | E3: Cycle (ngày) | F3: Weekday anchor | G3: Chuỗi anchor | H3: Điều kiện roll | I3: Kiểm tra bắt buộc
A4: AN1 | B4: Near — Friday | C4: Bổ sung Friday near phase 1 | D4: 46269 | E4: 28 | F4: Thứ Sáu | G4: 04/09/2026 → 02/10/2026 → 30/10/2026 → 27/11/2026 → 25/12/2026 | H4: Giữ đến hết ngày check-in; roll khi check-in < crawl date | I4: Ngày >= crawl date; khác 11 slot aux; không thuộc local 12 hoặc VPS 5 cùng ngày crawl
A5: AN2 | B5: Ngừng từ 03/09 | C5: Friday phase 2 chỉ giữ làm lịch sử cho lượt 02/09 | D5: 46276 | E5: 28 | F5: Thứ Sáu | G5: 11/09/2026 → 09/10/2026 → 06/11/2026 → 04/12/2026 | H5: Không roll sau 02/09 | I5: Không chọn từ 03/09
A6: AN3 | B6: Ngừng từ 03/09 | C6: Friday phase 3 chỉ giữ làm lịch sử cho lượt 02/09 | D6: 46283 | E6: 28 | F6: Thứ Sáu | G6: 18/09/2026 → 16/10/2026 → 13/11/2026 → 11/12/2026 | H6: Không roll sau 02/09 | I6: Không chọn từ 03/09
A7: AN4 | B7: Near — Friday | C7: Bổ sung Friday near phase 4 | D7: 46290 | E7: 28 | F7: Thứ Sáu | G7: 25/09/2026 → 23/10/2026 → 20/11/2026 → 18/12/2026 | H7: Giữ đến hết ngày check-in; roll khi check-in < crawl date | I7: Ngày >= crawl date; khác 11 slot aux; không thuộc local 12 hoặc VPS 5 cùng ngày crawl
A8: AN5 | B8: Near — Monday | C8: Cân bằng Monday ở dải lead 0–27 | D8: 46272 | E8: 28 | F8: Thứ Hai | G8: 07/09/2026 → 05/10/2026 → 02/11/2026 → 30/11/2026 → 28/12/2026 | H8: Giữ đến hết ngày check-in; roll khi check-in < crawl date | I8: Ngày >= crawl date; khác 11 slot aux; không thuộc local 12 hoặc VPS 5 cùng ngày crawl
A9: AN6 | B9: Near — Monday | C9: Cân bằng Monday, lệch phase AN5 | D9: 46286 | E9: 28 | F9: Thứ Hai | G9: 21/09/2026 → 19/10/2026 → 16/11/2026 → 14/12/2026 | H9: Giữ đến hết ngày check-in; roll khi check-in < crawl date | I9: Ngày >= crawl date; khác 11 slot aux; không thuộc local 12 hoặc VPS 5 cùng ngày crawl
A10: AN7 | B10: Near — Tuesday | C10: Cân bằng Tuesday ở dải lead 0–27 | D10: 46273 | E10: 28 | F10: Thứ Ba | G10: 08/09/2026 → 06/10/2026 → 03/11/2026 → 01/12/2026 | H10: Giữ đến hết ngày check-in; roll khi check-in < crawl date | I10: Ngày >= crawl date; khác 11 slot aux; không thuộc local 12 hoặc VPS 5 cùng ngày crawl
A11: AN8 | B11: Near — Tuesday | C11: Cân bằng Tuesday, lệch phase AN7 | D11: 46280 | E11: 28 | F11: Thứ Ba | G11: 15/09/2026 → 13/10/2026 → 10/11/2026 → 08/12/2026 | H11: Giữ đến hết ngày check-in; roll khi check-in < crawl date | I11: Ngày >= crawl date; khác 11 slot aux; không thuộc local 12 hoặc VPS 5 cùng ngày crawl
A12: AN9 | B12: Near — Sunday | C12: Đưa Sunday lên mức phủ cân bằng | D12: 46285 | E12: 28 | F12: Chủ Nhật | G12: 20/09/2026 → 18/10/2026 → 15/11/2026 → 13/12/2026 | H12: Giữ đến hết ngày check-in; roll khi check-in < crawl date | I12: Ngày >= crawl date; khác 11 slot aux; không thuộc local 12 hoặc VPS 5 cùng ngày crawl
A13: AF1 | B13: Far — Monday | C13: Phủ lead time 0–69 và Monday vùng medium/far | D13: 46321 | E13: 70 | F13: Thứ Hai | G13: 26/10/2026 → 04/01/2027 | H13: Giữ đến hết ngày check-in; roll khi check-in < crawl date | I13: Ngày >= crawl date; khác 11 slot aux; không thuộc local 12 hoặc VPS 5 cùng ngày crawl
